ERROR:root:Module modules.prediction에서 오류 발생: Traceback (most recent call last):
  File "/Users/choenamho/Documents/GitHub/mini-project-2/Home.py", line 49, in <module>
    module = __import__(mod_path, fromlist=[ui_func_name])
  File "/Users/choenamho/Documents/GitHub/mini-project-2/modules/prediction.py", line 5, in <module>
    from tensorflow.keras.models import Sequential, load_model
ModuleNotFoundError: No module named 'tensorflow'

ERROR:root:Module modules.prediction에서 오류 발생: Traceback (most recent call last):
  File "/Users/choenamho/Documents/GitHub/mini-project-2/Home.py", line 49, in <module>
    module = __import__(mod_path, fromlist=[ui_func_name])
  File "/Users/choenamho/Documents/GitHub/mini-project-2/modules/prediction.py", line 5, in <module>
    from tensorflow.keras.models import Sequential, load_model
ModuleNotFoundError: No module named 'tensorflow'

ERROR:root:Module modules.prediction에서 오류 발생: Traceback (most recent call last):
  File "/Users/choenamho/Documents/GitHub/mini-project-2/Home.py", line 49, in <module>
    module = __import__(mod_path, fromlist=[ui_func_name])
  File "/Users/choenamho/Documents/GitHub/mini-project-2/modules/prediction.py", line 5, in <module>
    from tensorflow.keras.models import Sequential, load_model
ModuleNotFoundError: No module named 'tensorflow'

ERROR:root:Module modules.prediction에서 오류 발생: Traceback (most recent call last):
  File "/Users/choenamho/Documents/GitHub/mini-project-2/Home.py", line 49, in <module>
    module = __import__(mod_path, fromlist=[ui_func_name])
  File "/Users/choenamho/Documents/GitHub/mini-project-2/modules/prediction.py", line 5, in <module>
    from tensorflow.keras.models import Sequential, load_model
ModuleNotFoundError: No module named 'tensorflow'

ERROR:root:Module modules.prediction에서 오류 발생: Traceback (most recent call last):
  File "/Users/choenamho/Documents/GitHub/mini-project-2/Home.py", line 49, in <module>
    module = __import__(mod_path, fromlist=[ui_func_name])
  File "/Users/choenamho/Documents/GitHub/mini-project-2/modules/prediction.py", line 5, in <module>
    from tensorflow.keras.models import Sequential, load_model
ModuleNotFoundError: No module named 'tensorflow'

ERROR:root:Module modules.prediction에서 오류 발생: Traceback (most recent call last):
  File "/Users/choenamho/Documents/GitHub/mini-project-2/Home.py", line 49, in <module>
    module = __import__(mod_path, fromlist=[ui_func_name])
  File "/Users/choenamho/Documents/GitHub/mini-project-2/modules/prediction.py", line 5, in <module>
    from tensorflow.keras.models import Sequential, load_model
ModuleNotFoundError: No module named 'tensorflow'

ERROR:root:Module modules.prediction에서 오류 발생: Traceback (most recent call last):
  File "/Users/choenamho/Documents/GitHub/mini-project-2/Home.py", line 49, in <module>
    module = __import__(mod_path, fromlist=[ui_func_name])
  File "/Users/choenamho/Documents/GitHub/mini-project-2/modules/prediction.py", line 5, in <module>
    from tensorflow.keras.models import Sequential, load_model
ModuleNotFoundError: No module named 'tensorflow'

ERROR:root:Module modules.prediction에서 오류 발생: Traceback (most recent call last):
  File "/Users/choenamho/Documents/GitHub/mini-project-2/Home.py", line 49, in <module>
    module = __import__(mod_path, fromlist=[ui_func_name])
  File "/Users/choenamho/Documents/GitHub/mini-project-2/modules/prediction.py", line 5, in <module>
    from tensorflow.keras.models import Sequential, load_model
ModuleNotFoundError: No module named 'tensorflow'

ERROR:root:Module modules.prediction에서 오류 발생: Traceback (most recent call last):
  File "/Users/choenamho/Documents/GitHub/mini-project-2/Home.py", line 49, in <module>
    module = __import__(mod_path, fromlist=[ui_func_name])
  File "/Users/choenamho/Documents/GitHub/mini-project-2/modules/prediction.py", line 5, in <module>
    from tensorflow.keras.models import Sequential, load_model
ModuleNotFoundError: No module named 'tensorflow'

ERROR:root:Module modules.inventory에서 오류 발생: Traceback (most recent call last):
  File "/Users/choenamho/Documents/GitHub/mini-project-2/Home.py", line 49, in <module>
    getattr(module, ui_func_name)()
  File "/Users/choenamho/Documents/GitHub/mini-project-2/modules/inventory.py", line 67, in inventory_ui
    year_sel = st.selectbox("연도 선택", available_years, index=available_years.index(default_year))
  File "/Users/choenamho/hi/lib/python3.10/site-packages/streamlit/runtime/metrics_util.py", line 410, in wrapped_func
    result = non_optional_func(*args, **kwargs)
  File "/Users/choenamho/hi/lib/python3.10/site-packages/streamlit/elements/widgets/selectbox.py", line 251, in selectbox
    return self._selectbox(
  File "/Users/choenamho/hi/lib/python3.10/site-packages/streamlit/elements/widgets/selectbox.py", line 297, in _selectbox
    element_id = compute_and_register_element_id(
  File "/Users/choenamho/hi/lib/python3.10/site-packages/streamlit/elements/lib/utils.py", line 241, in compute_and_register_element_id
    _register_element_id(ctx, element_type, element_id)
  File "/Users/choenamho/hi/lib/python3.10/site-packages/streamlit/elements/lib/utils.py", line 147, in _register_element_id
    raise StreamlitDuplicateElementId(element_type)
streamlit.errors.StreamlitDuplicateElementId: There are multiple `selectbox` elements with the same auto-generated ID. When this element is created, it is assigned an internal ID based on the element type and provided parameters. Multiple elements with the same type and parameters will cause this error.

To fix this error, please pass a unique `key` argument to the `selectbox` element.

ERROR:root:Module modules.inventory에서 오류 발생: Traceback (most recent call last):
  File "/Users/choenamho/Documents/GitHub/mini-project-2/Home.py", line 49, in <module>
    getattr(module, ui_func_name)()
  File "/Users/choenamho/Documents/GitHub/mini-project-2/modules/inventory.py", line 67, in inventory_ui
    year_sel = st.selectbox("연도 선택", available_years, index=available_years.index(default_year))
  File "/Users/choenamho/hi/lib/python3.10/site-packages/streamlit/runtime/metrics_util.py", line 410, in wrapped_func
    result = non_optional_func(*args, **kwargs)
  File "/Users/choenamho/hi/lib/python3.10/site-packages/streamlit/elements/widgets/selectbox.py", line 251, in selectbox
    return self._selectbox(
  File "/Users/choenamho/hi/lib/python3.10/site-packages/streamlit/elements/widgets/selectbox.py", line 297, in _selectbox
    element_id = compute_and_register_element_id(
  File "/Users/choenamho/hi/lib/python3.10/site-packages/streamlit/elements/lib/utils.py", line 241, in compute_and_register_element_id
    _register_element_id(ctx, element_type, element_id)
  File "/Users/choenamho/hi/lib/python3.10/site-packages/streamlit/elements/lib/utils.py", line 147, in _register_element_id
    raise StreamlitDuplicateElementId(element_type)
streamlit.errors.StreamlitDuplicateElementId: There are multiple `selectbox` elements with the same auto-generated ID. When this element is created, it is assigned an internal ID based on the element type and provided parameters. Multiple elements with the same type and parameters will cause this error.

To fix this error, please pass a unique `key` argument to the `selectbox` element.

ERROR:root:Module modules.inventory에서 오류 발생: Traceback (most recent call last):
  File "/Users/choenamho/Documents/GitHub/mini-project-2/Home.py", line 49, in <module>
    getattr(module, ui_func_name)()
  File "/Users/choenamho/Documents/GitHub/mini-project-2/modules/inventory.py", line 67, in inventory_ui
    year_sel = st.selectbox("연도 선택", available_years, index=available_years.index(default_year))
  File "/Users/choenamho/hi/lib/python3.10/site-packages/streamlit/runtime/metrics_util.py", line 410, in wrapped_func
    result = non_optional_func(*args, **kwargs)
  File "/Users/choenamho/hi/lib/python3.10/site-packages/streamlit/elements/widgets/selectbox.py", line 251, in selectbox
    return self._selectbox(
  File "/Users/choenamho/hi/lib/python3.10/site-packages/streamlit/elements/widgets/selectbox.py", line 297, in _selectbox
    element_id = compute_and_register_element_id(
  File "/Users/choenamho/hi/lib/python3.10/site-packages/streamlit/elements/lib/utils.py", line 241, in compute_and_register_element_id
    _register_element_id(ctx, element_type, element_id)
  File "/Users/choenamho/hi/lib/python3.10/site-packages/streamlit/elements/lib/utils.py", line 147, in _register_element_id
    raise StreamlitDuplicateElementId(element_type)
streamlit.errors.StreamlitDuplicateElementId: There are multiple `selectbox` elements with the same auto-generated ID. When this element is created, it is assigned an internal ID based on the element type and provided parameters. Multiple elements with the same type and parameters will cause this error.

To fix this error, please pass a unique `key` argument to the `selectbox` element.

ERROR:root:Module modules.inventory에서 오류 발생: Traceback (most recent call last):
  File "/Users/choenamho/Documents/GitHub/mini-project-2/Home.py", line 49, in <module>
    getattr(module, ui_func_name)()
  File "/Users/choenamho/Documents/GitHub/mini-project-2/modules/inventory.py", line 67, in inventory_ui
    year_sel = st.selectbox("연도 선택", available_years, index=available_years.index(default_year))
  File "/Users/choenamho/hi/lib/python3.10/site-packages/streamlit/runtime/metrics_util.py", line 410, in wrapped_func
    result = non_optional_func(*args, **kwargs)
  File "/Users/choenamho/hi/lib/python3.10/site-packages/streamlit/elements/widgets/selectbox.py", line 251, in selectbox
    return self._selectbox(
  File "/Users/choenamho/hi/lib/python3.10/site-packages/streamlit/elements/widgets/selectbox.py", line 297, in _selectbox
    element_id = compute_and_register_element_id(
  File "/Users/choenamho/hi/lib/python3.10/site-packages/streamlit/elements/lib/utils.py", line 241, in compute_and_register_element_id
    _register_element_id(ctx, element_type, element_id)
  File "/Users/choenamho/hi/lib/python3.10/site-packages/streamlit/elements/lib/utils.py", line 147, in _register_element_id
    raise StreamlitDuplicateElementId(element_type)
streamlit.errors.StreamlitDuplicateElementId: There are multiple `selectbox` elements with the same auto-generated ID. When this element is created, it is assigned an internal ID based on the element type and provided parameters. Multiple elements with the same type and parameters will cause this error.

To fix this error, please pass a unique `key` argument to the `selectbox` element.

ERROR:root:Module modules.inventory에서 오류 발생: Traceback (most recent call last):
  File "/Users/choenamho/Documents/GitHub/mini-project-2/Home.py", line 49, in <module>
    getattr(module, ui_func_name)()
  File "/Users/choenamho/Documents/GitHub/mini-project-2/modules/inventory.py", line 67, in inventory_ui
    year_sel = st.selectbox("연도 선택", available_years, index=available_years.index(default_year), key="inventory_year")
  File "/Users/choenamho/hi/lib/python3.10/site-packages/streamlit/runtime/metrics_util.py", line 410, in wrapped_func
    result = non_optional_func(*args, **kwargs)
  File "/Users/choenamho/hi/lib/python3.10/site-packages/streamlit/elements/widgets/selectbox.py", line 251, in selectbox
    return self._selectbox(
  File "/Users/choenamho/hi/lib/python3.10/site-packages/streamlit/elements/widgets/selectbox.py", line 297, in _selectbox
    element_id = compute_and_register_element_id(
  File "/Users/choenamho/hi/lib/python3.10/site-packages/streamlit/elements/lib/utils.py", line 241, in compute_and_register_element_id
    _register_element_id(ctx, element_type, element_id)
  File "/Users/choenamho/hi/lib/python3.10/site-packages/streamlit/elements/lib/utils.py", line 147, in _register_element_id
    raise StreamlitDuplicateElementId(element_type)
streamlit.errors.StreamlitDuplicateElementId: There are multiple `selectbox` elements with the same auto-generated ID. When this element is created, it is assigned an internal ID based on the element type and provided parameters. Multiple elements with the same type and parameters will cause this error.

To fix this error, please pass a unique `key` argument to the `selectbox` element.

ERROR:root:Module modules.inventory에서 오류 발생: Traceback (most recent call last):
  File "/Users/choenamho/Documents/GitHub/mini-project-2/Home.py", line 49, in <module>
    getattr(module, ui_func_name)()
  File "/Users/choenamho/Documents/GitHub/mini-project-2/modules/inventory.py", line 67, in inventory_ui
    year_sel = st.selectbox("연도 선택", available_years, index=available_years.index(default_year), key="inventory_year")
  File "/Users/choenamho/hi/lib/python3.10/site-packages/streamlit/runtime/metrics_util.py", line 410, in wrapped_func
    result = non_optional_func(*args, **kwargs)
  File "/Users/choenamho/hi/lib/python3.10/site-packages/streamlit/elements/widgets/selectbox.py", line 251, in selectbox
    return self._selectbox(
  File "/Users/choenamho/hi/lib/python3.10/site-packages/streamlit/elements/widgets/selectbox.py", line 297, in _selectbox
    element_id = compute_and_register_element_id(
  File "/Users/choenamho/hi/lib/python3.10/site-packages/streamlit/elements/lib/utils.py", line 241, in compute_and_register_element_id
    _register_element_id(ctx, element_type, element_id)
  File "/Users/choenamho/hi/lib/python3.10/site-packages/streamlit/elements/lib/utils.py", line 147, in _register_element_id
    raise StreamlitDuplicateElementId(element_type)
streamlit.errors.StreamlitDuplicateElementId: There are multiple `selectbox` elements with the same auto-generated ID. When this element is created, it is assigned an internal ID based on the element type and provided parameters. Multiple elements with the same type and parameters will cause this error.

To fix this error, please pass a unique `key` argument to the `selectbox` element.

ERROR:root:Module modules.inventory에서 오류 발생: Traceback (most recent call last):
  File "/Users/choenamho/Documents/GitHub/mini-project-2/Home.py", line 49, in <module>
    getattr(module, ui_func_name)()
  File "/Users/choenamho/Documents/GitHub/mini-project-2/modules/inventory.py", line 67, in inventory_ui
    year_sel = st.selectbox("연도 선택", available_years, index=available_years.index(default_year), key="inventory_year")
  File "/Users/choenamho/hi/lib/python3.10/site-packages/streamlit/runtime/metrics_util.py", line 410, in wrapped_func
    result = non_optional_func(*args, **kwargs)
  File "/Users/choenamho/hi/lib/python3.10/site-packages/streamlit/elements/widgets/selectbox.py", line 251, in selectbox
    return self._selectbox(
  File "/Users/choenamho/hi/lib/python3.10/site-packages/streamlit/elements/widgets/selectbox.py", line 297, in _selectbox
    element_id = compute_and_register_element_id(
  File "/Users/choenamho/hi/lib/python3.10/site-packages/streamlit/elements/lib/utils.py", line 241, in compute_and_register_element_id
    _register_element_id(ctx, element_type, element_id)
  File "/Users/choenamho/hi/lib/python3.10/site-packages/streamlit/elements/lib/utils.py", line 147, in _register_element_id
    raise StreamlitDuplicateElementId(element_type)
streamlit.errors.StreamlitDuplicateElementId: There are multiple `selectbox` elements with the same auto-generated ID. When this element is created, it is assigned an internal ID based on the element type and provided parameters. Multiple elements with the same type and parameters will cause this error.

To fix this error, please pass a unique `key` argument to the `selectbox` element.

ERROR:root:Module modules.dashboard에서 오류 발생: Traceback (most recent call last):
  File "/Users/choenamho/Documents/GitHub/mini-project-2/Home.py", line 48, in <module>
    module = __import__(mod_path, fromlist=[ui_func_name])
  File "/Users/choenamho/Documents/GitHub/mini-project-2/modules/dashboard.py", line 10, in <module>
    from modules.dashboard_filter import render_filter_options
  File "/Users/choenamho/Documents/GitHub/mini-project-2/modules/dashboard_filter.py", line 18
    st.markdown("""</div>""", unsafe_allow_html=True)
                         ^
SyntaxError: unterminated triple-quoted string literal (detected at line 20)

ERROR:root:Module modules.dashboard에서 오류 발생: Traceback (most recent call last):
  File "/Users/choenamho/Documents/GitHub/mini-project-2/Home.py", line 48, in <module>
    module = __import__(mod_path, fromlist=[ui_func_name])
  File "/Users/choenamho/Documents/GitHub/mini-project-2/modules/dashboard.py", line 74
    st.markdown("""
IndentationError: unexpected indent

ERROR:root:Module modules.dashboard에서 오류 발생: Traceback (most recent call last):
  File "/Users/choenamho/Documents/GitHub/mini-project-2/Home.py", line 49, in <module>
    getattr(module, ui_func_name)()
  File "/Users/choenamho/Documents/GitHub/mini-project-2/modules/dashboard.py", line 79, in dashboard_ui
    year, company = render_filter_options(df)
  File "/Users/choenamho/Documents/GitHub/mini-project-2/modules/dashboard_filter.py", line 9, in render_filter_options
    with col1:
AttributeError: __enter__

ERROR:root:Module modules.dashboard에서 오류 발생: Traceback (most recent call last):
  File "/Users/choenamho/Documents/GitHub/mini-project-2/Home.py", line 49, in <module>
    getattr(module, ui_func_name)()
  File "/Users/choenamho/Documents/GitHub/mini-project-2/modules/dashboard.py", line 79, in dashboard_ui
    year, company = render_filter_options(df)
  File "/Users/choenamho/Documents/GitHub/mini-project-2/modules/dashboard_filter.py", line 9, in render_filter_options
    with col1:
AttributeError: __enter__

ERROR:root:Module modules.dashboard에서 오류 발생: Traceback (most recent call last):
  File "/Users/choenamho/Documents/GitHub/mini-project-2/Home.py", line 48, in <module>
    module = __import__(mod_path, fromlist=[ui_func_name])
  File "/Users/choenamho/Documents/GitHub/mini-project-2/modules/dashboard.py", line 10, in <module>
    from modules.dashboard_filter import render_filter_options
  File "/Users/choenamho/Documents/GitHub/mini-project-2/modules/dashboard_filter.py", line 13
    st.markdown("""</div>""", unsafe_allow_html=True)
                                                     ^
IndentationError: unindent does not match any outer indentation level

ERROR:root:Module modules.dashboard에서 오류 발생: Traceback (most recent call last):
  File "/Users/choenamho/Documents/GitHub/mini-project-2/Home.py", line 48, in <module>
    module = __import__(mod_path, fromlist=[ui_func_name])
  File "/Users/choenamho/Documents/GitHub/mini-project-2/modules/dashboard.py", line 76
    col1, col2 col3= st.columns([4, 1])
               ^^^^^^^^^^^^^^^^^^^^^^^^
SyntaxError: invalid syntax. Maybe you meant '==' or ':=' instead of '='?

ERROR:root:Module modules.dashboard에서 오류 발생: Traceback (most recent call last):
  File "/Users/choenamho/Documents/GitHub/mini-project-2/Home.py", line 48, in <module>
    module = __import__(mod_path, fromlist=[ui_func_name])
  File "/Users/choenamho/Documents/GitHub/mini-project-2/modules/dashboard.py", line 76
    col1, col2 col3= st.columns([4, 1, 1])
               ^^^^^^^^^^^^^^^^^^^^^^^^^^^
SyntaxError: invalid syntax. Maybe you meant '==' or ':=' instead of '='?

ERROR:root:Module modules.dashboard에서 오류 발생: Traceback (most recent call last):
  File "/Users/choenamho/Documents/GitHub/mini-project-2/Home.py", line 48, in <module>
    module = __import__(mod_path, fromlist=[ui_func_name])
  File "/Users/choenamho/Documents/GitHub/mini-project-2/modules/dashboard.py", line 76
    col1, col2 col3= st.columns([4, 1, 1])
               ^^^^^^^^^^^^^^^^^^^^^^^^^^^
SyntaxError: invalid syntax. Maybe you meant '==' or ':=' instead of '='?

ERROR:root:Module modules.dashboard에서 오류 발생: Traceback (most recent call last):
  File "/Users/choenamho/Documents/GitHub/mini-project-2/Home.py", line 48, in <module>
    module = __import__(mod_path, fromlist=[ui_func_name])
  File "/Users/choenamho/Documents/GitHub/mini-project-2/modules/dashboard.py", line 76
    col1, col2 col3= st.columns([4, 1, 1])
               ^^^^^^^^^^^^^^^^^^^^^^^^^^^
SyntaxError: invalid syntax. Maybe you meant '==' or ':=' instead of '='?

ERROR:root:Module modules.dashboard에서 오류 발생: Traceback (most recent call last):
  File "/Users/choenamho/Documents/GitHub/mini-project-2/Home.py", line 48, in <module>
    module = __import__(mod_path, fromlist=[ui_func_name])
  File "/Users/choenamho/Documents/GitHub/mini-project-2/modules/dashboard.py", line 76
    col1, col2 col3= st.columns([4, 1, 1])
               ^^^^^^^^^^^^^^^^^^^^^^^^^^^
SyntaxError: invalid syntax. Maybe you meant '==' or ':=' instead of '='?

ERROR:root:Module modules.dashboard에서 오류 발생: Traceback (most recent call last):
  File "/Users/choenamho/Documents/GitHub/mini-project-2/Home.py", line 48, in <module>
    module = __import__(mod_path, fromlist=[ui_func_name])
  File "/Users/choenamho/Documents/GitHub/mini-project-2/modules/dashboard.py", line 76
    col1, col2 col3= st.columns([4, 1, 1])
               ^^^^^^^^^^^^^^^^^^^^^^^^^^^
SyntaxError: invalid syntax. Maybe you meant '==' or ':=' instead of '='?

ERROR:root:Module modules.dashboard에서 오류 발생: Traceback (most recent call last):
  File "/Users/choenamho/Documents/GitHub/mini-project-2/Home.py", line 48, in <module>
    module = __import__(mod_path, fromlist=[ui_func_name])
  File "/Users/choenamho/Documents/GitHub/mini-project-2/modules/dashboard.py", line 76
    col1, col2 col3= st.columns([4, 1, 1])
               ^^^^^^^^^^^^^^^^^^^^^^^^^^^
SyntaxError: invalid syntax. Maybe you meant '==' or ':=' instead of '='?

ERROR:root:Module modules.dashboard에서 오류 발생: Traceback (most recent call last):
  File "/Users/choenamho/Documents/GitHub/mini-project-2/Home.py", line 48, in <module>
    module = __import__(mod_path, fromlist=[ui_func_name])
  File "/Users/choenamho/Documents/GitHub/mini-project-2/modules/dashboard.py", line 76
    col1, col2, col3= st.columns([4, 1, 1]
                                ^
SyntaxError: '(' was never closed

ERROR:root:Module modules.dashboard에서 오류 발생: Traceback (most recent call last):
  File "/Users/choenamho/Documents/GitHub/mini-project-2/Home.py", line 48, in <module>
    module = __import__(mod_path, fromlist=[ui_func_name])
  File "/Users/choenamho/Documents/GitHub/mini-project-2/modules/dashboard.py", line 70
    }col1, col2 = st.columns([4, 1])
     ^^^^
SyntaxError: invalid syntax

ERROR:root:Module modules.dashboard에서 오류 발생: Traceback (most recent call last):
  File "/Users/choenamho/Documents/GitHub/mini-project-2/Home.py", line 48, in <module>
    module = __import__(mod_path, fromlist=[ui_func_name])
  File "/Users/choenamho/Documents/GitHub/mini-project-2/modules/dashboard.py", line 70
    }col1, col2 = st.columns([1, 4])
     ^^^^
SyntaxError: invalid syntax

ERROR:root:Module modules.dashboard에서 오류 발생: Traceback (most recent call last):
  File "/Users/choenamho/Documents/GitHub/mini-project-2/Home.py", line 48, in <module>
    module = __import__(mod_path, fromlist=[ui_func_name])
  File "/Users/choenamho/Documents/GitHub/mini-project-2/modules/dashboard.py", line 70
    }col1, col2 = st.columns([1, 4])
     ^^^^
SyntaxError: invalid syntax

ERROR:root:Module modules.dashboard에서 오류 발생: Traceback (most recent call last):
  File "/Users/choenamho/Documents/GitHub/mini-project-2/Home.py", line 48, in <module>
    module = __import__(mod_path, fromlist=[ui_func_name])
  File "/Users/choenamho/Documents/GitHub/mini-project-2/modules/dashboard.py", line 70
    }col1, col2 = st.columns([1, 4])
     ^^^^
SyntaxError: invalid syntax

ERROR:root:Module modules.dashboard에서 오류 발생: Traceback (most recent call last):
  File "/Users/choenamho/Documents/GitHub/mini-project-2/Home.py", line 48, in <module>
    module = __import__(mod_path, fromlist=[ui_func_name])
  File "/Users/choenamho/Documents/GitHub/mini-project-2/modules/dashboard.py", line 70
    }col1, col2 = st.columns([1, 4])
     ^^^^
SyntaxError: invalid syntax

ERROR:root:Module modules.dashboard에서 오류 발생: Traceback (most recent call last):
  File "/Users/choenamho/Documents/GitHub/mini-project-2/Home.py", line 48, in <module>
    module = __import__(mod_path, fromlist=[ui_func_name])
  File "/Users/choenamho/Documents/GitHub/mini-project-2/modules/dashboard.py", line 70
    }col1, col2 = st.columns([1, 4])
     ^^^^
SyntaxError: invalid syntax

ERROR:root:Module modules.dashboard에서 오류 발생: Traceback (most recent call last):
  File "/Users/choenamho/Documents/GitHub/mini-project-2/Home.py", line 48, in <module>
    module = __import__(mod_path, fromlist=[ui_func_name])
  File "/Users/choenamho/Documents/GitHub/mini-project-2/modules/dashboard.py", line 70
    }col1, col2 = st.columns([1, 4])
     ^^^^
SyntaxError: invalid syntax

ERROR:root:Module modules.dashboard에서 오류 발생: Traceback (most recent call last):
  File "/Users/choenamho/Documents/GitHub/mini-project-2/Home.py", line 48, in <module>
    module = __import__(mod_path, fromlist=[ui_func_name])
  File "/Users/choenamho/Documents/GitHub/mini-project-2/modules/dashboard.py", line 75
    pass
    ^^^^
IndentationError: expected an indented block after 'with' statement on line 74

ERROR:root:Module modules.dashboard에서 오류 발생: Traceback (most recent call last):
  File "/Users/choenamho/Documents/GitHub/mini-project-2/Home.py", line 48, in <module>
    module = __import__(mod_path, fromlist=[ui_func_name])
  File "/Users/choenamho/Documents/GitHub/mini-project-2/modules/dashboard.py", line 75
    pass
    ^^^^
IndentationError: expected an indented block after 'with' statement on line 74

ERROR:root:Module modules.dashboard에서 오류 발생: Traceback (most recent call last):
  File "/Users/choenamho/Documents/GitHub/mini-project-2/Home.py", line 48, in <module>
    module = __import__(mod_path, fromlist=[ui_func_name])
  File "/Users/choenamho/Documents/GitHub/mini-project-2/modules/dashboard.py", line 75
    pass
    ^^^^
IndentationError: expected an indented block after 'with' statement on line 74

ERROR:root:Module modules.dashboard에서 오류 발생: Traceback (most recent call last):
  File "/Users/choenamho/Documents/GitHub/mini-project-2/Home.py", line 48, in <module>
    module = __import__(mod_path, fromlist=[ui_func_name])
  File "/Users/choenamho/Documents/GitHub/mini-project-2/modules/dashboard.py", line 76
    st.markdown("""
    ^^
IndentationError: expected an indented block after 'with' statement on line 74

ERROR:root:Module modules.dashboard에서 오류 발생: Traceback (most recent call last):
  File "/Users/choenamho/Documents/GitHub/mini-project-2/Home.py", line 48, in <module>
    module = __import__(mod_path, fromlist=[ui_func_name])
  File "/Users/choenamho/Documents/GitHub/mini-project-2/modules/dashboard.py", line 75
    st.markdown("""
    ^^
IndentationError: expected an indented block after 'with' statement on line 74

ERROR:root:Module modules.dashboard에서 오류 발생: Traceback (most recent call last):
  File "/Users/choenamho/Documents/GitHub/mini-project-2/Home.py", line 49, in <module>
    getattr(module, ui_func_name)()
  File "/Users/choenamho/Documents/GitHub/mini-project-2/modules/dashboard.py", line 95, in dashboard_ui
    render_kpi_card(kpi1, kpi2, kpi3)
  File "/Users/choenamho/Documents/GitHub/mini-project-2/modules/dashboard_kpi.py", line 28, in render_kpi_card
    col4, col5 = st.columns(2)
  File "/Users/choenamho/hi/lib/python3.10/site-packages/streamlit/runtime/metrics_util.py", line 410, in wrapped_func
    result = non_optional_func(*args, **kwargs)
  File "/Users/choenamho/hi/lib/python3.10/site-packages/streamlit/elements/layouts.py", line 383, in columns
    return [row._block(column_proto(w / total_weight)) for w in weights]
  File "/Users/choenamho/hi/lib/python3.10/site-packages/streamlit/elements/layouts.py", line 383, in <listcomp>
    return [row._block(column_proto(w / total_weight)) for w in weights]
  File "/Users/choenamho/hi/lib/python3.10/site-packages/streamlit/delta_generator.py", line 518, in _block
    _check_nested_element_violation(self, block_type, ancestor_block_types)
  File "/Users/choenamho/hi/lib/python3.10/site-packages/streamlit/delta_generator.py", line 590, in _check_nested_element_violation
    raise StreamlitAPIException(
streamlit.errors.StreamlitAPIException: Columns can only be placed inside other columns up to one level of nesting.

ERROR:root:Module modules.inventory에서 오류 발생: Traceback (most recent call last):
  File "/Users/choenamho/Documents/GitHub/mini-project-2/Home.py", line 49, in <module>
    getattr(module, ui_func_name)()
  File "/Users/choenamho/Documents/GitHub/mini-project-2/modules/inventory.py", line 48, in inventory_ui
    inventory_df = calculate_inventory(prod_df, sales_df)
  File "/Users/choenamho/Documents/GitHub/mini-project-2/modules/inventory.py", line 21, in calculate_inventory
    return inventory_df
NameError: name 'inventory_df' is not defined. Did you mean: 'inventory_ui'?

ERROR:root:Module modules.inventory에서 오류 발생: Traceback (most recent call last):
  File "/Users/choenamho/Documents/GitHub/mini-project-2/Home.py", line 49, in <module>
    getattr(module, ui_func_name)()
  File "/Users/choenamho/Documents/GitHub/mini-project-2/modules/inventory.py", line 48, in inventory_ui
    inventory_df = calculate_inventory(prod_df, sales_df)
  File "/Users/choenamho/Documents/GitHub/mini-project-2/modules/inventory.py", line 21, in calculate_inventory
    return inventory_df
NameError: name 'inventory_df' is not defined. Did you mean: 'inventory_ui'?

ERROR:root:Module modules.inventory에서 오류 발생: Traceback (most recent call last):
  File "/Users/choenamho/Documents/GitHub/mini-project-2/Home.py", line 49, in <module>
    getattr(module, ui_func_name)()
  File "/Users/choenamho/Documents/GitHub/mini-project-2/modules/inventory.py", line 48, in inventory_ui
    inventory_df = calculate_inventory(prod_df, sales_df)
  File "/Users/choenamho/Documents/GitHub/mini-project-2/modules/inventory.py", line 21, in calculate_inventory
    return inventory_df
NameError: name 'inventory_df' is not defined. Did you mean: 'inventory_ui'?

ERROR:root:Module modules.inventory에서 오류 발생: Traceback (most recent call last):
  File "/Users/choenamho/Documents/GitHub/mini-project-2/Home.py", line 48, in <module>
    module = __import__(mod_path, fromlist=[ui_func_name])
  File "/Users/choenamho/Documents/GitHub/mini-project-2/modules/inventory.py", line 11
    📌 예시: 생산/판매 데이터를 불러오고 처리하는 부분
    ^
SyntaxError: invalid character '📌' (U+1F4CC)

ERROR:root:Module modules.inventory에서 오류 발생: Traceback (most recent call last):
  File "/Users/choenamho/Documents/GitHub/mini-project-2/Home.py", line 49, in <module>
    getattr(module, ui_func_name)()
  File "/Users/choenamho/Documents/GitHub/mini-project-2/modules/inventory.py", line 51, in inventory_ui
    inventory_df = calculate_inventory(prod_df, sales_df)
  File "/Users/choenamho/Documents/GitHub/mini-project-2/modules/inventory.py", line 24, in calculate_inventory
    return inventory_df
NameError: name 'inventory_df' is not defined. Did you mean: 'inventory_ui'?

ERROR:root:Module modules.inventory에서 오류 발생: Traceback (most recent call last):
  File "/Users/choenamho/Documents/GitHub/mini-project-2/Home.py", line 49, in <module>
    getattr(module, ui_func_name)()
  File "/Users/choenamho/Documents/GitHub/mini-project-2/modules/inventory.py", line 51, in inventory_ui
    inventory_df = calculate_inventory(prod_df, sales_df)
  File "/Users/choenamho/Documents/GitHub/mini-project-2/modules/inventory.py", line 24, in calculate_inventory
    return inventory_df
NameError: name 'inventory_df' is not defined. Did you mean: 'inventory_ui'?

ERROR:root:Module modules.inventory에서 오류 발생: Traceback (most recent call last):
  File "/Users/choenamho/Documents/GitHub/mini-project-2/Home.py", line 49, in <module>
    getattr(module, ui_func_name)()
  File "/Users/choenamho/Documents/GitHub/mini-project-2/modules/inventory.py", line 51, in inventory_ui
    inventory_df = calculate_inventory(prod_df, sales_df)
  File "/Users/choenamho/Documents/GitHub/mini-project-2/modules/inventory.py", line 24, in calculate_inventory
    return inventory_df
NameError: name 'inventory_df' is not defined. Did you mean: 'inventory_ui'?

ERROR:root:Module modules.inventory에서 오류 발생: Traceback (most recent call last):
  File "/Users/choenamho/Documents/GitHub/mini-project-2/Home.py", line 49, in <module>
    getattr(module, ui_func_name)()
  File "/Users/choenamho/Documents/GitHub/mini-project-2/modules/inventory.py", line 51, in inventory_ui
    inventory_df = calculate_inventory(prod_df, sales_df)
  File "/Users/choenamho/Documents/GitHub/mini-project-2/modules/inventory.py", line 24, in calculate_inventory
    return inventory_df
NameError: name 'inventory_df' is not defined. Did you mean: 'inventory_ui'?

ERROR:root:Module modules.inventory에서 오류 발생: Traceback (most recent call last):
  File "/Users/choenamho/Documents/GitHub/mini-project-2/Home.py", line 49, in <module>
    getattr(module, ui_func_name)()
  File "/Users/choenamho/Documents/GitHub/mini-project-2/modules/inventory.py", line 53, in inventory_ui
    inventory_df = calculate_inventory(prod_df, sales_df)
  File "/Users/choenamho/Documents/GitHub/mini-project-2/modules/inventory.py", line 26, in calculate_inventory
    return inventory_df
NameError: name 'inventory_df' is not defined. Did you mean: 'inventory_ui'?

ERROR:root:Module modules.inventory에서 오류 발생: Traceback (most recent call last):
  File "/Users/choenamho/Documents/GitHub/mini-project-2/Home.py", line 49, in <module>
    getattr(module, ui_func_name)()
  File "/Users/choenamho/Documents/GitHub/mini-project-2/modules/inventory.py", line 53, in inventory_ui
    inventory_df = calculate_inventory(prod_df, sales_df)
  File "/Users/choenamho/Documents/GitHub/mini-project-2/modules/inventory.py", line 26, in calculate_inventory
    return inventory_df
NameError: name 'inventory_df' is not defined. Did you mean: 'inventory_ui'?

ERROR:root:Module modules.inventory에서 오류 발생: Traceback (most recent call last):
  File "/Users/choenamho/Documents/GitHub/mini-project-2/Home.py", line 49, in <module>
    getattr(module, ui_func_name)()
  File "/Users/choenamho/Documents/GitHub/mini-project-2/modules/inventory.py", line 53, in inventory_ui
    inventory_df = calculate_inventory(prod_df, sales_df)
  File "/Users/choenamho/Documents/GitHub/mini-project-2/modules/inventory.py", line 26, in calculate_inventory
    return inventory_df
NameError: name 'inventory_df' is not defined. Did you mean: 'inventory_ui'?

ERROR:root:Module modules.inventory에서 오류 발생: Traceback (most recent call last):
  File "/Users/choenamho/Documents/GitHub/mini-project-2/Home.py", line 49, in <module>
    getattr(module, ui_func_name)()
  File "/Users/choenamho/Documents/GitHub/mini-project-2/modules/inventory.py", line 53, in inventory_ui
    inventory_df = calculate_inventory(prod_df, sales_df)
  File "/Users/choenamho/Documents/GitHub/mini-project-2/modules/inventory.py", line 26, in calculate_inventory
    return inventory_df
NameError: name 'inventory_df' is not defined. Did you mean: 'inventory_ui'?

ERROR:root:Module modules.inventory에서 오류 발생: Traceback (most recent call last):
  File "/Users/choenamho/Documents/GitHub/mini-project-2/Home.py", line 49, in <module>
    getattr(module, ui_func_name)()
  File "/Users/choenamho/Documents/GitHub/mini-project-2/modules/inventory.py", line 55, in inventory_ui
    inventory_df = calculate_inventory(prod_df, sales_df)
  File "/Users/choenamho/Documents/GitHub/mini-project-2/modules/inventory.py", line 26, in calculate_inventory
    return inventory_df
NameError: name 'inventory_df' is not defined. Did you mean: 'inventory_ui'?

ERROR:root:Module modules.inventory에서 오류 발생: Traceback (most recent call last):
  File "/Users/choenamho/Documents/GitHub/mini-project-2/Home.py", line 49, in <module>
    getattr(module, ui_func_name)()
  File "/Users/choenamho/Documents/GitHub/mini-project-2/modules/inventory.py", line 63, in inventory_ui
    inventory_df = calculate_inventory(prod_df, sales_df)
  File "/Users/choenamho/Documents/GitHub/mini-project-2/modules/inventory.py", line 34, in calculate_inventory
    return inventory_df
NameError: name 'inventory_df' is not defined. Did you mean: 'inventory_ui'?

ERROR:root:Module modules.inventory에서 오류 발생: Traceback (most recent call last):
  File "/Users/choenamho/Documents/GitHub/mini-project-2/Home.py", line 48, in <module>
    module = __import__(mod_path, fromlist=[ui_func_name])
  File "/Users/choenamho/Documents/GitHub/mini-project-2/modules/inventory.py", line 74
    4. 차트 렌더링 함수
       ^^^^^^
SyntaxError: invalid syntax

ERROR:root:Module modules.inventory에서 오류 발생: Traceback (most recent call last):
  File "/Users/choenamho/Documents/GitHub/mini-project-2/Home.py", line 49, in <module>
    getattr(module, ui_func_name)()
  File "/Users/choenamho/Documents/GitHub/mini-project-2/modules/inventory.py", line 102, in inventory_ui
    col1, co
UnboundLocalError: local variable 'col1' referenced before assignment

ERROR:root:Module modules.inventory에서 오류 발생: Traceback (most recent call last):
  File "/Users/choenamho/Documents/GitHub/mini-project-2/Home.py", line 49, in <module>
    getattr(module, ui_func_name)()
  File "/Users/choenamho/Documents/GitHub/mini-project-2/modules/inventory.py", line 102, in inventory_ui
    col1, co
UnboundLocalError: local variable 'col1' referenced before assignment

ERROR:root:Module modules.inventory에서 오류 발생: Traceback (most recent call last):
  File "/Users/choenamho/Documents/GitHub/mini-project-2/Home.py", line 49, in <module>
    getattr(module, ui_func_name)()
  File "/Users/choenamho/Documents/GitHub/mini-project-2/modules/inventory.py", line 102, in inventory_ui
    col1, col2
UnboundLocalError: local variable 'col1' referenced before assignment

ERROR:root:Module modules.inventory에서 오류 발생: Traceback (most recent call last):
  File "/Users/choenamho/Documents/GitHub/mini-project-2/Home.py", line 49, in <module>
    getattr(module, ui_func_name)()
  File "/Users/choenamho/Documents/GitHub/mini-project-2/modules/inventory.py", line 102, in inventory_ui
    col1, col2
UnboundLocalError: local variable 'col1' referenced before assignment

ERROR:root:Module modules.inventory에서 오류 발생: Traceback (most recent call last):
  File "/Users/choenamho/Documents/GitHub/mini-project-2/Home.py", line 48, in <module>
    module = __import__(mod_path, fromlist=[ui_func_name])
  File "/Users/choenamho/Documents/GitHub/mini-project-2/modules/inventory.py", line 102
    col1, col2 = 
                 ^
SyntaxError: invalid syntax

ERROR:root:Module modules.inventory에서 오류 발생: Traceback (most recent call last):
  File "/Users/choenamho/Documents/GitHub/mini-project-2/Home.py", line 48, in <module>
    module = __import__(mod_path, fromlist=[ui_func_name])
  File "/Users/choenamho/Documents/GitHub/mini-project-2/modules/inventory.py", line 102
    col1, col2 = 
                 ^
SyntaxError: invalid syntax

ERROR:root:Module modules.inventory에서 오류 발생: Traceback (most recent call last):
  File "/Users/choenamho/Documents/GitHub/mini-project-2/Home.py", line 49, in <module>
    getattr(module, ui_func_name)()
  File "/Users/choenamho/Documents/GitHub/mini-project-2/modules/inventory.py", line 102, in inventory_ui
    col1, col2 = colm
NameError: name 'colm' is not defined

ERROR:root:Module modules.inventory에서 오류 발생: Traceback (most recent call last):
  File "/Users/choenamho/Documents/GitHub/mini-project-2/Home.py", line 49, in <module>
    getattr(module, ui_func_name)()
  File "/Users/choenamho/Documents/GitHub/mini-project-2/modules/inventory.py", line 102, in inventory_ui
    col1, col2 = colm
NameError: name 'colm' is not defined

ERROR:root:Module modules.inventory에서 오류 발생: Traceback (most recent call last):
  File "/Users/choenamho/Documents/GitHub/mini-project-2/Home.py", line 49, in <module>
    getattr(module, ui_func_name)()
  File "/Users/choenamho/Documents/GitHub/mini-project-2/modules/inventory.py", line 102, in inventory_ui
    col1, col2 = col
NameError: name 'col' is not defined

ERROR:root:Module modules.inventory에서 오류 발생: Traceback (most recent call last):
  File "/Users/choenamho/Documents/GitHub/mini-project-2/Home.py", line 49, in <module>
    getattr(module, ui_func_name)()
  File "/Users/choenamho/Documents/GitHub/mini-project-2/modules/inventory.py", line 102, in inventory_ui
    col1, col2 = col
NameError: name 'col' is not defined

ERROR:root:Module modules.inventory에서 오류 발생: Traceback (most recent call last):
  File "/Users/choenamho/Documents/GitHub/mini-project-2/Home.py", line 49, in <module>
    getattr(module, ui_func_name)()
  File "/Users/choenamho/Documents/GitHub/mini-project-2/modules/inventory.py", line 102, in inventory_ui
    col1, col2 = cu
NameError: name 'cu' is not defined

ERROR:root:Module modules.inventory에서 오류 발생: Traceback (most recent call last):
  File "/Users/choenamho/Documents/GitHub/mini-project-2/Home.py", line 49, in <module>
    getattr(module, ui_func_name)()
  File "/Users/choenamho/Documents/GitHub/mini-project-2/modules/inventory.py", line 102, in inventory_ui
    col1, col2 = cu
NameError: name 'cu' is not defined

ERROR:root:Module modules.inventory에서 오류 발생: Traceback (most recent call last):
  File "/Users/choenamho/Documents/GitHub/mini-project-2/Home.py", line 49, in <module>
    getattr(module, ui_func_name)()
  File "/Users/choenamho/Documents/GitHub/mini-project-2/modules/inventory.py", line 102, in inventory_ui
    col1, col2 = c
NameError: name 'c' is not defined

ERROR:root:Module modules.inventory에서 오류 발생: Traceback (most recent call last):
  File "/Users/choenamho/Documents/GitHub/mini-project-2/Home.py", line 49, in <module>
    getattr(module, ui_func_name)()
  File "/Users/choenamho/Documents/GitHub/mini-project-2/modules/inventory.py", line 102, in inventory_ui
    col1, col2 = c
NameError: name 'c' is not defined

ERROR:root:Module modules.inventory에서 오류 발생: Traceback (most recent call last):
  File "/Users/choenamho/Documents/GitHub/mini-project-2/Home.py", line 49, in <module>
    getattr(module, ui_func_name)()
  File "/Users/choenamho/Documents/GitHub/mini-project-2/modules/inventory.py", line 102, in inventory_ui
    col1, col2, col3= st.columns([4, 5])
ValueError: not enough values to unpack (expected 3, got 2)

ERROR:root:Module modules.inventory에서 오류 발생: Traceback (most recent call last):
  File "/Users/choenamho/Documents/GitHub/mini-project-2/Home.py", line 49, in <module>
    getattr(module, ui_func_name)()
  File "/Users/choenamho/Documents/GitHub/mini-project-2/modules/inventory.py", line 102, in inventory_ui
    col1, col2, col3= st.columns([4, 5])
ValueError: not enough values to unpack (expected 3, got 2)

ERROR:root:Module modules.inventory에서 오류 발생: Traceback (most recent call last):
  File "/Users/choenamho/Documents/GitHub/mini-project-2/Home.py", line 49, in <module>
    getattr(module, ui_func_name)()
  File "/Users/choenamho/Documents/GitHub/mini-project-2/modules/inventory.py", line 102, in inventory_ui
    col1, col2, col3= st.columns([1, 5])
ValueError: not enough values to unpack (expected 3, got 2)

ERROR:root:Module modules.inventory에서 오류 발생: Traceback (most recent call last):
  File "/Users/choenamho/Documents/GitHub/mini-project-2/Home.py", line 49, in <module>
    getattr(module, ui_func_name)()
  File "/Users/choenamho/Documents/GitHub/mini-project-2/modules/inventory.py", line 102, in inventory_ui
    col1, col2, col3= st.columns([1, 5])
ValueError: not enough values to unpack (expected 3, got 2)

ERROR:root:Module modules.inventory에서 오류 발생: Traceback (most recent call last):
  File "/Users/choenamho/Documents/GitHub/mini-project-2/Home.py", line 49, in <module>
    getattr(module, ui_func_name)()
  File "/Users/choenamho/Documents/GitHub/mini-project-2/modules/inventory.py", line 104, in inventory_ui
    whi
NameError: name 'whi' is not defined

ERROR:root:Module modules.inventory에서 오류 발생: Traceback (most recent call last):
  File "/Users/choenamho/Documents/GitHub/mini-project-2/Home.py", line 49, in <module>
    getattr(module, ui_func_name)()
  File "/Users/choenamho/Documents/GitHub/mini-project-2/modules/inventory.py", line 104, in inventory_ui
    whi
NameError: name 'whi' is not defined

ERROR:root:Module modules.inventory에서 오류 발생: Traceback (most recent call last):
  File "/Users/choenamho/Documents/GitHub/mini-project-2/Home.py", line 48, in <module>
    module = __import__(mod_path, fromlist=[ui_func_name])
  File "/Users/choenamho/Documents/GitHub/mini-project-2/modules/inventory.py", line 104
    with col1
             ^
SyntaxError: expected ':'

ERROR:root:Module modules.inventory에서 오류 발생: Traceback (most recent call last):
  File "/Users/choenamho/Documents/GitHub/mini-project-2/Home.py", line 48, in <module>
    module = __import__(mod_path, fromlist=[ui_func_name])
  File "/Users/choenamho/Documents/GitHub/mini-project-2/modules/inventory.py", line 104
    with col1
             ^
SyntaxError: expected ':'

ERROR:root:Module modules.inventory에서 오류 발생: Traceback (most recent call last):
  File "/Users/choenamho/Documents/GitHub/mini-project-2/Home.py", line 48, in <module>
    module = __import__(mod_path, fromlist=[ui_func_name])
  File "/Users/choenamho/Documents/GitHub/mini-project-2/modules/inventory.py", line 105
    brand_list = ["전체"] + inventory_df["브랜드"].unique().tolist()
    ^^^^^^^^^^
IndentationError: expected an indented block after 'with' statement on line 104

ERROR:root:Module modules.inventory에서 오류 발생: Traceback (most recent call last):
  File "/Users/choenamho/Documents/GitHub/mini-project-2/Home.py", line 48, in <module>
    module = __import__(mod_path, fromlist=[ui_func_name])
  File "/Users/choenamho/Documents/GitHub/mini-project-2/modules/inventory.py", line 105
    brand_list = ["전체"] + inventory_df["브랜드"].unique().tolist()
    ^^^^^^^^^^
IndentationError: expected an indented block after 'with' statement on line 104

ERROR:root:Module modules.inventory에서 오류 발생: Traceback (most recent call last):
  File "/Users/choenamho/Documents/GitHub/mini-project-2/Home.py", line 48, in <module>
    module = __import__(mod_path, fromlist=[ui_func_name])
  File "/Users/choenamho/Documents/GitHub/mini-project-2/modules/inventory.py", line 117
    prod, sales, stock, low, high = get_kpi_summary(filtered)
    ^^^^
IndentationError: expected an indented block after 'with' statement on line 115

ERROR:root:Module modules.inventory에서 오류 발생: Traceback (most recent call last):
  File "/Users/choenamho/Documents/GitHub/mini-project-2/Home.py", line 48, in <module>
    module = __import__(mod_path, fromlist=[ui_func_name])
  File "/Users/choenamho/Documents/GitHub/mini-project-2/modules/inventory.py", line 117
    prod, sales, stock, low, high = get_kpi_summary(filtered)
    ^^^^
IndentationError: expected an indented block after 'with' statement on line 115

ERROR:root:Module modules.inventory에서 오류 발생: Traceback (most recent call last):
  File "/Users/choenamho/Documents/GitHub/mini-project-2/Home.py", line 48, in <module>
    module = __import__(mod_path, fromlist=[ui_func_name])
  File "/Users/choenamho/Documents/GitHub/mini-project-2/modules/inventory.py", line 117
    prod, sales, stock, low, high = get_kpi_summary(filtered)
    ^^^^
IndentationError: expected an indented block after 'with' statement on line 115

ERROR:root:Module modules.inventory에서 오류 발생: Traceback (most recent call last):
  File "/Users/choenamho/Documents/GitHub/mini-project-2/Home.py", line 48, in <module>
    module = __import__(mod_path, fromlist=[ui_func_name])
  File "/Users/choenamho/Documents/GitHub/mini-project-2/modules/inventory.py", line 117
    prod, sales, stock, low, high = get_kpi_summary(filtered)
    ^^^^
IndentationError: expected an indented block after 'with' statement on line 115

ERROR:root:Module modules.inventory에서 오류 발생: Traceback (most recent call last):
  File "/Users/choenamho/Documents/GitHub/mini-project-2/Home.py", line 48, in <module>
    module = __import__(mod_path, fromlist=[ui_func_name])
  File "/Users/choenamho/Documents/GitHub/mini-project-2/modules/inventory.py", line 118
    prod, sales, stock, low, high = get_kpi_summary(filtered)
    ^^^^
IndentationError: expected an indented block after 'with' statement on line 116

ERROR:root:Module modules.inventory에서 오류 발생: Traceback (most recent call last):
  File "/Users/choenamho/Documents/GitHub/mini-project-2/Home.py", line 48, in <module>
    module = __import__(mod_path, fromlist=[ui_func_name])
  File "/Users/choenamho/Documents/GitHub/mini-project-2/modules/inventory.py", line 118
    prod, sales, stock, low, high = get_kpi_summary(filtered)
    ^^^^
IndentationError: expected an indented block after 'with' statement on line 116

ERROR:root:Module modules.inventory에서 오류 발생: Traceback (most recent call last):
  File "/Users/choenamho/Documents/GitHub/mini-project-2/Home.py", line 48, in <module>
    module = __import__(mod_path, fromlist=[ui_func_name])
  File "/Users/choenamho/Documents/GitHub/mini-project-2/modules/inventory.py", line 117
    prod, sales, stock, low, high = get_kpi_summary(filtered)
    ^^^^
IndentationError: expected an indented block after 'with' statement on line 116

ERROR:root:Module modules.inventory에서 오류 발생: Traceback (most recent call last):
  File "/Users/choenamho/Documents/GitHub/mini-project-2/Home.py", line 48, in <module>
    module = __import__(mod_path, fromlist=[ui_func_name])
  File "/Users/choenamho/Documents/GitHub/mini-project-2/modules/inventory.py", line 117
    prod, sales, stock, low, high = get_kpi_summary(filtered)
    ^^^^
IndentationError: expected an indented block after 'with' statement on line 116

ERROR:root:Module modules.inventory에서 오류 발생: Traceback (most recent call last):
  File "/Users/choenamho/Documents/GitHub/mini-project-2/Home.py", line 48, in <module>
    module = __import__(mod_path, fromlist=[ui_func_name])
  File "/Users/choenamho/Documents/GitHub/mini-project-2/modules/inventory.py", line 117
    st.
       ^
SyntaxError: invalid syntax

ERROR:root:Module modules.inventory에서 오류 발생: Traceback (most recent call last):
  File "/Users/choenamho/Documents/GitHub/mini-project-2/Home.py", line 48, in <module>
    module = __import__(mod_path, fromlist=[ui_func_name])
  File "/Users/choenamho/Documents/GitHub/mini-project-2/modules/inventory.py", line 117
    st.
       ^
SyntaxError: invalid syntax

ERROR:root:Module modules.inventory에서 오류 발생: Traceback (most recent call last):
  File "/Users/choenamho/Documents/GitHub/mini-project-2/Home.py", line 48, in <module>
    module = __import__(mod_path, fromlist=[ui_func_name])
  File "/Users/choenamho/Documents/GitHub/mini-project-2/modules/inventory.py", line 117
    st.
       ^
SyntaxError: invalid syntax

ERROR:root:Module modules.inventory에서 오류 발생: Traceback (most recent call last):
  File "/Users/choenamho/Documents/GitHub/mini-project-2/Home.py", line 49, in <module>
    getattr(module, ui_func_name)()
  File "/Users/choenamho/Documents/GitHub/mini-project-2/modules/inventory.py", line 117, in inventory_ui
    st.ma
AttributeError: module 'streamlit' has no attribute 'ma'

ERROR:root:Module modules.inventory에서 오류 발생: Traceback (most recent call last):
  File "/Users/choenamho/Documents/GitHub/mini-project-2/Home.py", line 49, in <module>
    getattr(module, ui_func_name)()
  File "/Users/choenamho/Documents/GitHub/mini-project-2/modules/inventory.py", line 117, in inventory_ui
    st.ma
AttributeError: module 'streamlit' has no attribute 'ma'

ERROR:root:Module modules.inventory에서 오류 발생: Traceback (most recent call last):
  File "/Users/choenamho/Documents/GitHub/mini-project-2/Home.py", line 49, in <module>
    getattr(module, ui_func_name)()
  File "/Users/choenamho/Documents/GitHub/mini-project-2/modules/inventory.py", line 117, in inventory_ui
    st.markdown()
  File "/Users/choenamho/hi/lib/python3.10/site-packages/streamlit/runtime/metrics_util.py", line 410, in wrapped_func
    result = non_optional_func(*args, **kwargs)
TypeError: MarkdownMixin.markdown() missing 1 required positional argument: 'body'

ERROR:root:Module modules.inventory에서 오류 발생: Traceback (most recent call last):
  File "/Users/choenamho/Documents/GitHub/mini-project-2/Home.py", line 49, in <module>
    getattr(module, ui_func_name)()
  File "/Users/choenamho/Documents/GitHub/mini-project-2/modules/inventory.py", line 117, in inventory_ui
    st.markdown()
  File "/Users/choenamho/hi/lib/python3.10/site-packages/streamlit/runtime/metrics_util.py", line 410, in wrapped_func
    result = non_optional_func(*args, **kwargs)
TypeError: MarkdownMixin.markdown() missing 1 required positional argument: 'body'

ERROR:root:Module modules.inventory에서 오류 발생: Traceback (most recent call last):
  File "/Users/choenamho/Documents/GitHub/mini-project-2/Home.py", line 48, in <module>
    module = __import__(mod_path, fromlist=[ui_func_name])
  File "/Users/choenamho/Documents/GitHub/mini-project-2/modules/inventory.py", line 107
    st.markdown("""
    ^^
IndentationError: expected an indented block after 'with' statement on line 106

ERROR:root:Module modules.inventory에서 오류 발생: Traceback (most recent call last):
  File "/Users/choenamho/Documents/GitHub/mini-project-2/Home.py", line 48, in <module>
    module = __import__(mod_path, fromlist=[ui_func_name])
  File "/Users/choenamho/Documents/GitHub/mini-project-2/modules/inventory.py", line 107
    st.markdown("""
    ^^
IndentationError: expected an indented block after 'with' statement on line 106

ERROR:root:Module modules.inventory에서 오류 발생: Traceback (most recent call last):
  File "/Users/choenamho/Documents/GitHub/mini-project-2/Home.py", line 48, in <module>
    module = __import__(mod_path, fromlist=[ui_func_name])
  File "/Users/choenamho/Documents/GitHub/mini-project-2/modules/inventory.py", line 107
    st.markdown("""
    ^^
IndentationError: expected an indented block after 'with' statement on line 106

ERROR:root:Module modules.inventory에서 오류 발생: Traceback (most recent call last):
  File "/Users/choenamho/Documents/GitHub/mini-project-2/Home.py", line 48, in <module>
    module = __import__(mod_path, fromlist=[ui_func_name])
  File "/Users/choenamho/Documents/GitHub/mini-project-2/modules/inventory.py", line 107
    st.markdown("""
    ^^
IndentationError: expected an indented block after 'with' statement on line 106

ERROR:root:Module modules.inventory에서 오류 발생: Traceback (most recent call last):
  File "/Users/choenamho/Documents/GitHub/mini-project-2/Home.py", line 48, in <module>
    module = __import__(mod_path, fromlist=[ui_func_name])
  File "/Users/choenamho/Documents/GitHub/mini-project-2/modules/inventory.py", line 123
    st.markdown("""
                   ^
IndentationError: unindent does not match any outer indentation level

ERROR:root:Module modules.inventory에서 오류 발생: Traceback (most recent call last):
  File "/Users/choenamho/Documents/GitHub/mini-project-2/Home.py", line 48, in <module>
    module = __import__(mod_path, fromlist=[ui_func_name])
  File "/Users/choenamho/Documents/GitHub/mini-project-2/modules/inventory.py", line 123
    st.markdown("""
                   ^
IndentationError: unindent does not match any outer indentation level

ERROR:root:Module modules.inventory에서 오류 발생: Traceback (most recent call last):
  File "/Users/choenamho/Documents/GitHub/mini-project-2/Home.py", line 48, in <module>
    module = __import__(mod_path, fromlist=[ui_func_name])
  File "/Users/choenamho/Documents/GitHub/mini-project-2/modules/inventory.py", line 118
    filtered = filtered[filtered["브랜드"] == brand_sel]
    ^^^^^^^^
IndentationError: expected an indented block after 'if' statement on line 117

ERROR:root:Module modules.inventory에서 오류 발생: Traceback (most recent call last):
  File "/Users/choenamho/Documents/GitHub/mini-project-2/Home.py", line 48, in <module>
    module = __import__(mod_path, fromlist=[ui_func_name])
  File "/Users/choenamho/Documents/GitHub/mini-project-2/modules/inventory.py", line 118
    filtered = filtered[filtered["브랜드"] == brand_sel]
    ^^^^^^^^
IndentationError: expected an indented block after 'if' statement on line 117

ERROR:root:Module modules.inventory에서 오류 발생: Traceback (most recent call last):
  File "/Users/choenamho/Documents/GitHub/mini-project-2/Home.py", line 48, in <module>
    module = __import__(mod_path, fromlist=[ui_func_name])
  File "/Users/choenamho/Documents/GitHub/mini-project-2/modules/inventory.py", line 123
    st.header("주요 지표")
    ^^
IndentationError: expected an indented block after 'with' statement on line 122

ERROR:root:Module modules.inventory에서 오류 발생: Traceback (most recent call last):
  File "/Users/choenamho/Documents/GitHub/mini-project-2/Home.py", line 48, in <module>
    module = __import__(mod_path, fromlist=[ui_func_name])
  File "/Users/choenamho/Documents/GitHub/mini-project-2/modules/inventory.py", line 123
    st.header("주요 지표")
    ^^
IndentationError: expected an indented block after 'with' statement on line 122

ERROR:root:Module modules.inventory에서 오류 발생: Traceback (most recent call last):
  File "/Users/choenamho/Documents/GitHub/mini-project-2/Home.py", line 49, in <module>
    getattr(module, ui_func_name)()
  File "/Users/choenamho/Documents/GitHub/mini-project-2/modules/inventory.py", line 107, in inventory_ui
    st.녀ㅠheader("데이터 필터링")
AttributeError: module 'streamlit' has no attribute '녀ᅲheader'. Did you mean: 'header'?

ERROR:root:Module modules.inventory에서 오류 발생: Traceback (most recent call last):
  File "/Users/choenamho/Documents/GitHub/mini-project-2/Home.py", line 49, in <module>
    getattr(module, ui_func_name)()
  File "/Users/choenamho/Documents/GitHub/mini-project-2/modules/inventory.py", line 107, in inventory_ui
    stheader("데이터 필터링")
NameError: name 'stheader' is not defined

ERROR:root:Module modules.inventory에서 오류 발생: Traceback (most recent call last):
  File "/Users/choenamho/Documents/GitHub/mini-project-2/Home.py", line 49, in <module>
    getattr(module, ui_func_name)()
  File "/Users/choenamho/Documents/GitHub/mini-project-2/modules/inventory.py", line 107, in inventory_ui
    stheader("데이터 필터링")
NameError: name 'stheader' is not defined

ERROR:root:Module modules.inventory에서 오류 발생: Traceback (most recent call last):
  File "/Users/choenamho/Documents/GitHub/mini-project-2/Home.py", line 49, in <module>
    getattr(module, ui_func_name)()
  File "/Users/choenamho/Documents/GitHub/mini-project-2/modules/inventory.py", line 107, in inventory_ui
    stheader("데이터 필터링")
NameError: name 'stheader' is not defined

ERROR:root:Module modules.inventory에서 오류 발생: Traceback (most recent call last):
  File "/Users/choenamho/Documents/GitHub/mini-project-2/Home.py", line 49, in <module>
    getattr(module, ui_func_name)()
  File "/Users/choenamho/Documents/GitHub/mini-project-2/modules/inventory.py", line 102, in inventory_ui
    col1, col2, col2= st.columns([4, 1])
ValueError: not enough values to unpack (expected 3, got 2)

ERROR:root:Module modules.inventory에서 오류 발생: Traceback (most recent call last):
  File "/Users/choenamho/Documents/GitHub/mini-project-2/Home.py", line 49, in <module>
    getattr(module, ui_func_name)()
  File "/Users/choenamho/Documents/GitHub/mini-project-2/modules/inventory.py", line 102, in inventory_ui
    col1, col2, col3= st.columns([4, 1])
ValueError: not enough values to unpack (expected 3, got 2)

ERROR:root:Module modules.inventory에서 오류 발생: Traceback (most recent call last):
  File "/Users/choenamho/Documents/GitHub/mini-project-2/Home.py", line 49, in <module>
    getattr(module, ui_func_name)()
  File "/Users/choenamho/Documents/GitHub/mini-project-2/modules/inventory.py", line 102, in inventory_ui
    col1, col2, col3= st.columns([4, 1])
ValueError: not enough values to unpack (expected 3, got 2)

ERROR:root:Module modules.inventory에서 오류 발생: Traceback (most recent call last):
  File "/Users/choenamho/Documents/GitHub/mini-project-2/Home.py", line 49, in <module>
    getattr(module, ui_func_name)()
  File "/Users/choenamho/Documents/GitHub/mini-project-2/modules/inventory.py", line 102, in inventory_ui
    col1, col2, col3= st.columns([4, 1])
ValueError: not enough values to unpack (expected 3, got 2)

ERROR:root:Module modules.inventory에서 오류 발생: Traceback (most recent call last):
  File "/Users/choenamho/Documents/GitHub/mini-project-2/Home.py", line 49, in <module>
    getattr(module, ui_func_name)()
  File "/Users/choenamho/Documents/GitHub/mini-project-2/modules/inventory.py", line 102, in inventory_ui
    col1, col2, col3= st.columns(3[4, 1])
TypeError: 'int' object is not subscriptable

ERROR:root:Module modules.inventory에서 오류 발생: Traceback (most recent call last):
  File "/Users/choenamho/Documents/GitHub/mini-project-2/Home.py", line 49, in <module>
    getattr(module, ui_func_name)()
  File "/Users/choenamho/Documents/GitHub/mini-project-2/modules/inventory.py", line 102, in inventory_ui
    col1, col2, col3= st.columns(3[4, 1])
TypeError: 'int' object is not subscriptable

ERROR:root:Module modules.inventory에서 오류 발생: Traceback (most recent call last):
  File "/Users/choenamho/Documents/GitHub/mini-project-2/Home.py", line 49, in <module>
    getattr(module, ui_func_name)()
  File "/Users/choenamho/Documents/GitHub/mini-project-2/modules/inventory.py", line 102, in inventory_ui
    col1, col2, col3= st.columns([4, 1])
ValueError: not enough values to unpack (expected 3, got 2)

ERROR:root:Module modules.inventory에서 오류 발생: Traceback (most recent call last):
  File "/Users/choenamho/Documents/GitHub/mini-project-2/Home.py", line 49, in <module>
    getattr(module, ui_func_name)()
  File "/Users/choenamho/Documents/GitHub/mini-project-2/modules/inventory.py", line 102, in inventory_ui
    col1, col2, col3= st.columns([4, 1])
ValueError: not enough values to unpack (expected 3, got 2)

ERROR:root:Module modules.inventory에서 오류 발생: Traceback (most recent call last):
  File "/Users/choenamho/Documents/GitHub/mini-project-2/Home.py", line 49, in <module>
    getattr(module, ui_func_name)()
  File "/Users/choenamho/Documents/GitHub/mini-project-2/modules/inventory.py", line 102, in inventory_ui
    col1, col2, col3= st.columns([3, 1])
ValueError: not enough values to unpack (expected 3, got 2)

ERROR:root:Module modules.inventory에서 오류 발생: Traceback (most recent call last):
  File "/Users/choenamho/Documents/GitHub/mini-project-2/Home.py", line 48, in <module>
    module = __import__(mod_path, fromlist=[ui_func_name])
  File "/Users/choenamho/Documents/GitHub/mini-project-2/modules/inventory.py", line 112
    available_years = sorted(inventory_df["연도"].unique(), reverse=True)
    ^^^^^^^^^^^^^^^
IndentationError: expected an indented block after 'with' statement on line 111

ERROR:root:Module modules.inventory에서 오류 발생: Traceback (most recent call last):
  File "/Users/choenamho/Documents/GitHub/mini-project-2/Home.py", line 48, in <module>
    module = __import__(mod_path, fromlist=[ui_func_name])
  File "/Users/choenamho/Documents/GitHub/mini-project-2/modules/inventory.py", line 112
    available_years = sorted(inventory_df["연도"].unique(), reverse=True)
    ^^^^^^^^^^^^^^^
IndentationError: expected an indented block after 'with' statement on line 111

ERROR:root:Module modules.inventory에서 오류 발생: Traceback (most recent call last):
  File "/Users/choenamho/Documents/GitHub/mini-project-2/Home.py", line 48, in <module>
    module = __import__(mod_path, fromlist=[ui_func_name])
  File "/Users/choenamho/Documents/GitHub/mini-project-2/modules/inventory.py", line 125
    prod, sales, stock, low, high = get_kpi_summary(filtered)
    ^^^^
IndentationError: expected an indented block after 'with' statement on line 124

ERROR:root:Module modules.inventory에서 오류 발생: Traceback (most recent call last):
  File "/Users/choenamho/Documents/GitHub/mini-project-2/Home.py", line 48, in <module>
    module = __import__(mod_path, fromlist=[ui_func_name])
  File "/Users/choenamho/Documents/GitHub/mini-project-2/modules/inventory.py", line 125
    prod, sales, stock, low, high = get_kpi_summary(filtered)
    ^^^^
IndentationError: expected an indented block after 'with' statement on line 124

ERROR:root:Module modules.inventory에서 오류 발생: Traceback (most recent call last):
  File "/Users/choenamho/Documents/GitHub/mini-project-2/Home.py", line 48, in <module>
    module = __import__(mod_path, fromlist=[ui_func_name])
  File "/Users/choenamho/Documents/GitHub/mini-project-2/modules/inventory.py", line 128
    prod, sales, stock, low, high = get_kpi_summary(filtered)
IndentationError: unexpected indent

ERROR:root:Module modules.inventory에서 오류 발생: Traceback (most recent call last):
  File "/Users/choenamho/Documents/GitHub/mini-project-2/Home.py", line 48, in <module>
    module = __import__(mod_path, fromlist=[ui_func_name])
  File "/Users/choenamho/Documents/GitHub/mini-project-2/modules/inventory.py", line 128
    prod, sales, stock, low, high = get_kpi_summary(filtered)
IndentationError: unexpected indent

ERROR:root:Module modules.inventory에서 오류 발생: Traceback (most recent call last):
  File "/Users/choenamho/Documents/GitHub/mini-project-2/Home.py", line 48, in <module>
    module = __import__(mod_path, fromlist=[ui_func_name])
  File "/Users/choenamho/Documents/GitHub/mini-project-2/modules/inventory.py", line 124
    st.markdown(            prod, sales, stock, low, high = get_kpi_summary(filtered)
                                                            
SyntaxError: invalid syntax. Perhaps you forgot a comma?

ERROR:root:Module modules.inventory에서 오류 발생: Traceback (most recent call last):
  File "/Users/choenamho/Documents/GitHub/mini-project-2/Home.py", line 48, in <module>
    module = __import__(mod_path, fromlist=[ui_func_name])
  File "/Users/choenamho/Documents/GitHub/mini-project-2/modules/inventory.py", line 124
    st.markdown(            prod, sales, stock, low, high = get_kpi_summary(filtered)
                                                            
SyntaxError: invalid syntax. Perhaps you forgot a comma?

ERROR:root:Module modules.inventory에서 오류 발생: Traceback (most recent call last):
  File "/Users/choenamho/Documents/GitHub/mini-project-2/Home.py", line 48, in <module>
    module = __import__(mod_path, fromlist=[ui_func_name])
  File "/Users/choenamho/Documents/GitHub/mini-project-2/modules/inventory.py", line 125
    prod, sales, stock, low, high = get_kpi_summary(filtered)
                                    
SyntaxError: invalid syntax. Perhaps you forgot a comma?

ERROR:root:Module modules.inventory에서 오류 발생: Traceback (most recent call last):
  File "/Users/choenamho/Documents/GitHub/mini-project-2/Home.py", line 48, in <module>
    module = __import__(mod_path, fromlist=[ui_func_name])
  File "/Users/choenamho/Documents/GitHub/mini-project-2/modules/inventory.py", line 125
    prod, sales, stock, low, high = get_kpi_summary(filtered)
                                    
SyntaxError: invalid syntax. Perhaps you forgot a comma?

ERROR:root:Module modules.inventory에서 오류 발생: Traceback (most recent call last):
  File "/Users/choenamho/Documents/GitHub/mini-project-2/Home.py", line 48, in <module>
    module = __import__(mod_path, fromlist=[ui_func_name])
  File "/Users/choenamho/Documents/GitHub/mini-project-2/modules/inventory.py", line 128
    prod, sales, stock, low, high = get_kpi_summary(filtered)
IndentationError: unexpected indent

ERROR:root:Module modules.inventory에서 오류 발생: Traceback (most recent call last):
  File "/Users/choenamho/Documents/GitHub/mini-project-2/Home.py", line 48, in <module>
    module = __import__(mod_path, fromlist=[ui_func_name])
  File "/Users/choenamho/Documents/GitHub/mini-project-2/modules/inventory.py", line 128
    prod, sales, stock, low, high = get_kpi_summary(filtered)
IndentationError: unexpected indent

ERROR:root:Module modules.inventory에서 오류 발생: Traceback (most recent call last):
  File "/Users/choenamho/Documents/GitHub/mini-project-2/Home.py", line 48, in <module>
    module = __import__(mod_path, fromlist=[ui_func_name])
  File "/Users/choenamho/Documents/GitHub/mini-project-2/modules/inventory.py", line 124, in <module>
    brand_list = ["전체"] + inventory_df["브랜드"].unique().tolist()
NameError: name 'inventory_df' is not defined. Did you mean: 'inventory_ui'?

ERROR:root:Module modules.inventory에서 오류 발생: Traceback (most recent call last):
  File "/Users/choenamho/Documents/GitHub/mini-project-2/Home.py", line 48, in <module>
    module = __import__(mod_path, fromlist=[ui_func_name])
  File "/Users/choenamho/Documents/GitHub/mini-project-2/modules/inventory.py", line 124, in <module>
    brand_list = ["전체"] + inventory_df["브랜드"].unique().tolist()
NameError: name 'inventory_df' is not defined. Did you mean: 'inventory_ui'?

ERROR:root:Module modules.inventory에서 오류 발생: Traceback (most recent call last):
  File "/Users/choenamho/Documents/GitHub/mini-project-2/Home.py", line 49, in <module>
    getattr(module, ui_func_name)()
  File "/Users/choenamho/Documents/GitHub/mini-project-2/modules/inventory.py", line 139, in inventory_ui
    prod, sales, stock, low, high = get_kpi_summary(filtered)
NameError: name 'filtered' is not defined. Did you mean: 'filter'?

ERROR:root:Module modules.inventory에서 오류 발생: Traceback (most recent call last):
  File "/Users/choenamho/Documents/GitHub/mini-project-2/Home.py", line 49, in <module>
    getattr(module, ui_func_name)()
  File "/Users/choenamho/Documents/GitHub/mini-project-2/modules/inventory.py", line 139, in inventory_ui
    prod, sales, stock, low, high = get_kpi_summary(filtered)
NameError: name 'filtered' is not defined. Did you mean: 'filter'?

ERROR:root:Module modules.inventory에서 오류 발생: Traceback (most recent call last):
  File "/Users/choenamho/Documents/GitHub/mini-project-2/Home.py", line 48, in <module>
    module = __import__(mod_path, fromlist=[ui_func_name])
  File "/Users/choenamho/Documents/GitHub/mini-project-2/modules/inventory.py", line 139
    prod, sales, stock, low, high = get_kpi_summary(filtered)
                                                             ^
IndentationError: unindent does not match any outer indentation level

ERROR:root:Module modules.inventory에서 오류 발생: Traceback (most recent call last):
  File "/Users/choenamho/Documents/GitHub/mini-project-2/Home.py", line 48, in <module>
    module = __import__(mod_path, fromlist=[ui_func_name])
  File "/Users/choenamho/Documents/GitHub/mini-project-2/modules/inventory.py", line 139
    prod, sales, stock, low, high = get_kpi_summary(filtered)
                                                             ^
IndentationError: unindent does not match any outer indentation level

ERROR:root:Module modules.inventory에서 오류 발생: Traceback (most recent call last):
  File "/Users/choenamho/Documents/GitHub/mini-project-2/Home.py", line 48, in <module>
    module = __import__(mod_path, fromlist=[ui_func_name])
  File "/Users/choenamho/Documents/GitHub/mini-project-2/modules/inventory.py", line 139
    prod, sales, stock, low, high = get_kpi_summary(filtered)
                                                             ^
IndentationError: unindent does not match any outer indentation level

ERROR:root:Module modules.inventory에서 오류 발생: Traceback (most recent call last):
  File "/Users/choenamho/Documents/GitHub/mini-project-2/Home.py", line 48, in <module>
    module = __import__(mod_path, fromlist=[ui_func_name])
  File "/Users/choenamho/Documents/GitHub/mini-project-2/modules/inventory.py", line 139
    prod, sales, stock, low, high = get_kpi_summary(filtered)
                                                             ^
IndentationError: unindent does not match any outer indentation level

ERROR:root:Module modules.inventory에서 오류 발생: Traceback (most recent call last):
  File "/Users/choenamho/Documents/GitHub/mini-project-2/Home.py", line 49, in <module>
    getattr(module, ui_func_name)()
  File "/Users/choenamho/Documents/GitHub/mini-project-2/modules/inventory.py", line 139, in inventory_ui
    prod, sales, stock, low, high = get_kpi_summary(filtered)
NameError: name 'filtered' is not defined. Did you mean: 'filter'?

ERROR:root:Module modules.inventory에서 오류 발생: Traceback (most recent call last):
  File "/Users/choenamho/Documents/GitHub/mini-project-2/Home.py", line 49, in <module>
    getattr(module, ui_func_name)()
  File "/Users/choenamho/Documents/GitHub/mini-project-2/modules/inventory.py", line 139, in inventory_ui
    prod, sales, stock, low, high = get_kpi_summary(filtered)
NameError: name 'filtered' is not defined. Did you mean: 'filter'?

ERROR:root:Module modules.inventory에서 오류 발생: Traceback (most recent call last):
  File "/Users/choenamho/Documents/GitHub/mini-project-2/Home.py", line 49, in <module>
    getattr(module, ui_func_name)()
  File "/Users/choenamho/Documents/GitHub/mini-project-2/modules/inventory.py", line 138, in inventory_ui
    prod, sales, stock, low, high = get_kpi_summary(filtered)
NameError: name 'filtered' is not defined. Did you mean: 'filter'?

ERROR:root:Module modules.inventory에서 오류 발생: Traceback (most recent call last):
  File "/Users/choenamho/Documents/GitHub/mini-project-2/Home.py", line 49, in <module>
    getattr(module, ui_func_name)()
  File "/Users/choenamho/Documents/GitHub/mini-project-2/modules/inventory.py", line 138, in inventory_ui
    prod, sales, stock, low, high = get_kpi_summary(filtered)
NameError: name 'filtered' is not defined. Did you mean: 'filter'?

ERROR:root:Module modules.inventory에서 오류 발생: Traceback (most recent call last):
  File "/Users/choenamho/Documents/GitHub/mini-project-2/Home.py", line 49, in <module>
    getattr(module, ui_func_name)()
  File "/Users/choenamho/Documents/GitHub/mini-project-2/modules/inventory.py", line 137, in inventory_ui
    prod, sales, stock, low, high = get_kpi_summary(filtered)
NameError: name 'filtered' is not defined. Did you mean: 'filter'?

ERROR:root:Module modules.inventory에서 오류 발생: Traceback (most recent call last):
  File "/Users/choenamho/Documents/GitHub/mini-project-2/Home.py", line 49, in <module>
    getattr(module, ui_func_name)()
  File "/Users/choenamho/Documents/GitHub/mini-project-2/modules/inventory.py", line 137, in inventory_ui
    prod, sales, stock, low, high = get_kpi_summary(filtered)
NameError: name 'filtered' is not defined. Did you mean: 'filter'?

ERROR:root:Module modules.inventory에서 오류 발생: Traceback (most recent call last):
  File "/Users/choenamho/Documents/GitHub/mini-project-2/Home.py", line 49, in <module>
    getattr(module, ui_func_name)()
  File "/Users/choenamho/Documents/GitHub/mini-project-2/modules/inventory.py", line 138, in inventory_ui
    prod, sales, stock, low, high = get_kpi_summary(filtered)
NameError: name 'filtered' is not defined. Did you mean: 'filter'?

ERROR:root:Module modules.inventory에서 오류 발생: Traceback (most recent call last):
  File "/Users/choenamho/Documents/GitHub/mini-project-2/Home.py", line 49, in <module>
    getattr(module, ui_func_name)()
  File "/Users/choenamho/Documents/GitHub/mini-project-2/modules/inventory.py", line 139, in inventory_ui
    prod, sales, stock, low, high = get_kpi_summary(filtered)
NameError: name 'filtered' is not defined. Did you mean: 'filter'?

ERROR:root:Module modules.inventory에서 오류 발생: Traceback (most recent call last):
  File "/Users/choenamho/Documents/GitHub/mini-project-2/Home.py", line 49, in <module>
    getattr(module, ui_func_name)()
  File "/Users/choenamho/Documents/GitHub/mini-project-2/modules/inventory.py", line 139, in inventory_ui
    prod, sales, stock, low, high = get_kpi_summary(filtered)
NameError: name 'filtered' is not defined. Did you mean: 'filter'?

ERROR:root:Module modules.inventory에서 오류 발생: Traceback (most recent call last):
  File "/Users/choenamho/Documents/GitHub/mini-project-2/Home.py", line 49, in <module>
    getattr(module, ui_func_name)()
  File "/Users/choenamho/Documents/GitHub/mini-project-2/modules/inventory.py", line 139, in inventory_ui
    prod, sales, stock, low, high = get_kpi_summary(filtered)
NameError: name 'filtered' is not defined. Did you mean: 'filter'?

ERROR:root:Module modules.inventory에서 오류 발생: Traceback (most recent call last):
  File "/Users/choenamho/Documents/GitHub/mini-project-2/Home.py", line 48, in <module>
    module = __import__(mod_path, fromlist=[ui_func_name])
  File "/Users/choenamho/Documents/GitHub/mini-project-2/modules/inventory.py", line 138
    st.markdown('</div>', unsafe_allow_html=True)
IndentationError: unexpected indent

ERROR:root:Module modules.inventory에서 오류 발생: Traceback (most recent call last):
  File "/Users/choenamho/Documents/GitHub/mini-project-2/Home.py", line 48, in <module>
    module = __import__(mod_path, fromlist=[ui_func_name])
  File "/Users/choenamho/Documents/GitHub/mini-project-2/modules/inventory.py", line 138
    st.markdown('</div>', unsafe_allow_html=True)
IndentationError: unexpected indent

ERROR:root:Module modules.inventory에서 오류 발생: Traceback (most recent call last):
  File "/Users/choenamho/Documents/GitHub/mini-project-2/Home.py", line 49, in <module>
    getattr(module, ui_func_name)()
  File "/Users/choenamho/Documents/GitHub/mini-project-2/modules/inventory.py", line 140, in inventory_ui
    col1.dataframe(top10[["브랜드", "차종", "연도", "재고변동"]].style.hide_index(), use_container_width=True)
AttributeError: 'Styler' object has no attribute 'hide_index'. Did you mean: 'hide_index_'?

ERROR:root:Module modules.inventory에서 오류 발생: Traceback (most recent call last):
  File "/Users/choenamho/Documents/GitHub/mini-project-2/Home.py", line 49, in <module>
    getattr(module, ui_func_name)()
  File "/Users/choenamho/Documents/GitHub/mini-project-2/modules/inventory.py", line 140, in inventory_ui
    col1.dataframe(top10[["브랜드", "차종", "연도", "재고변동"]].style.hide_index(), use_container_width=True)
AttributeError: 'Styler' object has no attribute 'hide_index'. Did you mean: 'hide_index_'?

ERROR:root:Module modules.inventory에서 오류 발생: Traceback (most recent call last):
  File "/Users/choenamho/Documents/GitHub/mini-project-2/Home.py", line 48, in <module>
    module = __import__(mod_path, fromlist=[ui_func_name])
  File "/Users/choenamho/Documents/GitHub/mini-project-2/modules/inventory.py", line 145
    st.subheader("📋 필터 결과 상세 데이터")
IndentationError: unexpected indent

ERROR:root:Module modules.inventory에서 오류 발생: Traceback (most recent call last):
  File "/Users/choenamho/Documents/GitHub/mini-project-2/Home.py", line 48, in <module>
    module = __import__(mod_path, fromlist=[ui_func_name])
  File "/Users/choenamho/Documents/GitHub/mini-project-2/modules/inventory.py", line 145
    st.subheader("📋 필터 결과 상세 데이터")
IndentationError: unexpected indent

ERROR:root:Module modules.inventory에서 오류 발생: Traceback (most recent call last):
  File "/Users/choenamho/Documents/GitHub/mini-project-2/Home.py", line 49, in <module>
    getattr(module, ui_func_name)()
  File "/Users/choenamho/Documents/GitHub/mini-project-2/modules/inventory.py", line 146, in inventory_ui
    st.dataframe(filtered.sort_values("재고변동").style.hide_index(), use_container_width=True)
AttributeError: 'Styler' object has no attribute 'hide_index'. Did you mean: 'hide_index_'?

ERROR:root:Module modules.inventory에서 오류 발생: Traceback (most recent call last):
  File "/Users/choenamho/Documents/GitHub/mini-project-2/Home.py", line 49, in <module>
    getattr(module, ui_func_name)()
  File "/Users/choenamho/Documents/GitHub/mini-project-2/modules/inventory.py", line 146, in inventory_ui
    st.dataframe(filtered.sort_values("재고변동").style.hide_index(), use_container_width=True)
AttributeError: 'Styler' object has no attribute 'hide_index'. Did you mean: 'hide_index_'?

ERROR:root:Module modules.inventory에서 오류 발생: Traceback (most recent call last):
  File "/Users/choenamho/Documents/GitHub/mini-project-2/Home.py", line 48, in <module>
    module = __import__(mod_path, fromlist=[ui_func_name])
  File "/Users/choenamho/Documents/GitHub/mini-project-2/modules/inventory.py", line 133, in <module>
    st.altair_chart(draw_inventory_chart(filtered), use_container_width=True)
NameError: name 'filtered' is not defined. Did you mean: 'filter'?

ERROR:root:Module modules.inventory에서 오류 발생: Traceback (most recent call last):
  File "/Users/choenamho/Documents/GitHub/mini-project-2/Home.py", line 48, in <module>
    module = __import__(mod_path, fromlist=[ui_func_name])
  File "/Users/choenamho/Documents/GitHub/mini-project-2/modules/inventory.py", line 133, in <module>
    st.altair_chart(draw_inventory_chart(filtered), use_container_width=True)
NameError: name 'filtered' is not defined. Did you mean: 'filter'?

ERROR:root:Module modules.inventory에서 오류 발생: Traceback (most recent call last):
  File "/Users/choenamho/Documents/GitHub/mini-project-2/Home.py", line 49, in <module>
    getattr(module, ui_func_name)()
  File "/Users/choenamho/Documents/GitHub/mini-project-2/modules/inventory.py", line 146, in inventory_ui
    st.dataframe(filtered.sort_values("재고변동").style.hide_index(), use_container_width=True)
AttributeError: 'Styler' object has no attribute 'hide_index'. Did you mean: 'hide_index_'?

ERROR:root:Module modules.inventory에서 오류 발생: Traceback (most recent call last):
  File "/Users/choenamho/Documents/GitHub/mini-project-2/Home.py", line 49, in <module>
    getattr(module, ui_func_name)()
  File "/Users/choenamho/Documents/GitHub/mini-project-2/modules/inventory.py", line 146, in inventory_ui
    st.dataframe(filtered.sort_values("재고변동").style.hide_index(), use_container_width=True)
AttributeError: 'Styler' object has no attribute 'hide_index'. Did you mean: 'hide_index_'?

ERROR:root:Module modules.inventory에서 오류 발생: Traceback (most recent call last):
  File "/Users/choenamho/Documents/GitHub/mini-project-2/Home.py", line 49, in <module>
    getattr(module, ui_func_name)()
  File "/Users/choenamho/Documents/GitHub/mini-project-2/modules/inventory.py", line 146, in inventory_ui
    st.dataframe(filtered.sort_values("재고변동").style.hide_index(), use_container_width=True)
AttributeError: 'Styler' object has no attribute 'hide_index'. Did you mean: 'hide_index_'?

ERROR:root:Module modules.inventory에서 오류 발생: Traceback (most recent call last):
  File "/Users/choenamho/Documents/GitHub/mini-project-2/Home.py", line 49, in <module>
    getattr(module, ui_func_name)()
  File "/Users/choenamho/Documents/GitHub/mini-project-2/modules/inventory.py", line 146, in inventory_ui
    st.dataframe(filtered.sort_values("재고변동").style.hide_index(), use_container_width=True)
AttributeError: 'Styler' object has no attribute 'hide_index'. Did you mean: 'hide_index_'?

ERROR:root:Module modules.inventory에서 오류 발생: Traceback (most recent call last):
  File "/Users/choenamho/Documents/GitHub/mini-project-2/Home.py", line 49, in <module>
    getattr(module, ui_func_name)()
  File "/Users/choenamho/Documents/GitHub/mini-project-2/modules/inventory.py", line 146, in inventory_ui
    st.dataframe(filtered.sort_values("재고변동").style.hide_index(), use_container_width=True)
AttributeError: 'Styler' object has no attribute 'hide_index'. Did you mean: 'hide_index_'?

ERROR:root:Module modules.inventory에서 오류 발생: Traceback (most recent call last):
  File "/Users/choenamho/Documents/GitHub/mini-project-2/Home.py", line 49, in <module>
    getattr(module, ui_func_name)()
  File "/Users/choenamho/Documents/GitHub/mini-project-2/modules/inventory.py", line 146, in inventory_ui
    st.dataframe(filtered.sort_values("재고변동").style.hide_index(), use_container_width=True)
AttributeError: 'Styler' object has no attribute 'hide_index'. Did you mean: 'hide_index_'?

ERROR:root:Module modules.inventory에서 오류 발생: Traceback (most recent call last):
  File "/Users/choenamho/Documents/GitHub/mini-project-2/Home.py", line 49, in <module>
    getattr(module, ui_func_name)()
  File "/Users/choenamho/Documents/GitHub/mini-project-2/modules/inventory.py", line 134, in inventory_ui
    col1, col2, = st.columns([4, 1,1])
ValueError: too many values to unpack (expected 2)

ERROR:root:Module modules.inventory에서 오류 발생: Traceback (most recent call last):
  File "/Users/choenamho/Documents/GitHub/mini-project-2/Home.py", line 49, in <module>
    getattr(module, ui_func_name)()
  File "/Users/choenamho/Documents/GitHub/mini-project-2/modules/inventory.py", line 134, in inventory_ui
    col1, col2, = st.columns([4, 1,1])
ValueError: too many values to unpack (expected 2)

ERROR:root:Module modules.inventory에서 오류 발생: Traceback (most recent call last):
  File "/Users/choenamho/Documents/GitHub/mini-project-2/Home.py", line 49, in <module>
    getattr(module, ui_func_name)()
  File "/Users/choenamho/Documents/GitHub/mini-project-2/modules/inventory.py", line 134, in inventory_ui
    col1, col2, = st.columns([])
  File "/Users/choenamho/hi/lib/python3.10/site-packages/streamlit/runtime/metrics_util.py", line 410, in wrapped_func
    result = non_optional_func(*args, **kwargs)
  File "/Users/choenamho/hi/lib/python3.10/site-packages/streamlit/elements/layouts.py", line 341, in columns
    raise StreamlitInvalidColumnSpecError()
streamlit.errors.StreamlitInvalidColumnSpecError: The `spec` argument to `st.columns` must be either a positive integer (number of columns) or a list of positive numbers (width ratios of the columns). See [documentation](https://docs.streamlit.io/develop/api-reference/layout/st.columns) for more information.

ERROR:root:Module modules.inventory에서 오류 발생: Traceback (most recent call last):
  File "/Users/choenamho/Documents/GitHub/mini-project-2/Home.py", line 49, in <module>
    getattr(module, ui_func_name)()
  File "/Users/choenamho/Documents/GitHub/mini-project-2/modules/inventory.py", line 134, in inventory_ui
    col1, col2, = st.columns([])
  File "/Users/choenamho/hi/lib/python3.10/site-packages/streamlit/runtime/metrics_util.py", line 410, in wrapped_func
    result = non_optional_func(*args, **kwargs)
  File "/Users/choenamho/hi/lib/python3.10/site-packages/streamlit/elements/layouts.py", line 341, in columns
    raise StreamlitInvalidColumnSpecError()
streamlit.errors.StreamlitInvalidColumnSpecError: The `spec` argument to `st.columns` must be either a positive integer (number of columns) or a list of positive numbers (width ratios of the columns). See [documentation](https://docs.streamlit.io/develop/api-reference/layout/st.columns) for more information.

ERROR:root:Module modules.inventory에서 오류 발생: Traceback (most recent call last):
  File "/Users/choenamho/Documents/GitHub/mini-project-2/Home.py", line 49, in <module>
    getattr(module, ui_func_name)()
  File "/Users/choenamho/Documents/GitHub/mini-project-2/modules/inventory.py", line 146, in inventory_ui
    st.dataframe(filtered.sort_values("재고변동").style.hide_index(), use_container_width=True)
AttributeError: 'Styler' object has no attribute 'hide_index'. Did you mean: 'hide_index_'?

ERROR:root:Module modules.inventory에서 오류 발생: Traceback (most recent call last):
  File "/Users/choenamho/Documents/GitHub/mini-project-2/Home.py", line 49, in <module>
    getattr(module, ui_func_name)()
  File "/Users/choenamho/Documents/GitHub/mini-project-2/modules/inventory.py", line 146, in inventory_ui
    st.dataframe(filtered.sort_values("재고변동").style.hide_index(), use_container_width=True)
AttributeError: 'Styler' object has no attribute 'hide_index'. Did you mean: 'hide_index_'?

ERROR:root:Module modules.inventory에서 오류 발생: Traceback (most recent call last):
  File "/Users/choenamho/Documents/GitHub/mini-project-2/Home.py", line 49, in <module>
    getattr(module, ui_func_name)()
  File "/Users/choenamho/Documents/GitHub/mini-project-2/modules/inventory.py", line 147, in inventory_ui
    st.dataframe(filtered.sort_values("재고변동").style.hide_index(), use_container_width=True)
AttributeError: 'Styler' object has no attribute 'hide_index'. Did you mean: 'hide_index_'?

ERROR:root:Module modules.inventory에서 오류 발생: Traceback (most recent call last):
  File "/Users/choenamho/Documents/GitHub/mini-project-2/Home.py", line 49, in <module>
    getattr(module, ui_func_name)()
  File "/Users/choenamho/Documents/GitHub/mini-project-2/modules/inventory.py", line 147, in inventory_ui
    st.dataframe(filtered.sort_values("재고변동").style.hide_index(), use_container_width=True)
AttributeError: 'Styler' object has no attribute 'hide_index'. Did you mean: 'hide_index_'?

ERROR:root:Module modules.inventory에서 오류 발생: Traceback (most recent call last):
  File "/Users/choenamho/Documents/GitHub/mini-project-2/Home.py", line 48, in <module>
    module = __import__(mod_path, fromlist=[ui_func_name])
  File "/Users/choenamho/Documents/GitHub/mini-project-2/modules/inventory.py", line 138, in <module>
    top10 = filtered.sort_values("재고변동", ascending=False).head(10).reset_index(drop=True)
NameError: name 'filtered' is not defined. Did you mean: 'filter'?

ERROR:root:Module modules.inventory에서 오류 발생: Traceback (most recent call last):
  File "/Users/choenamho/Documents/GitHub/mini-project-2/Home.py", line 48, in <module>
    module = __import__(mod_path, fromlist=[ui_func_name])
  File "/Users/choenamho/Documents/GitHub/mini-project-2/modules/inventory.py", line 138, in <module>
    top10 = filtered.sort_values("재고변동", ascending=False).head(10).reset_index(drop=True)
NameError: name 'filtered' is not defined. Did you mean: 'filter'?

ERROR:root:Module modules.inventory에서 오류 발생: Traceback (most recent call last):
  File "/Users/choenamho/Documents/GitHub/mini-project-2/Home.py", line 49, in <module>
    getattr(module, ui_func_name)()
  File "/Users/choenamho/Documents/GitHub/mini-project-2/modules/inventory.py", line 147, in inventory_ui
    filtered_sorted = filtered.sort_values("재고변동").reset_index(drop=True, hide_index=True)
TypeError: DataFrame.reset_index() got an unexpected keyword argument 'hide_index'

ERROR:root:Module modules.inventory에서 오류 발생: Traceback (most recent call last):
  File "/Users/choenamho/Documents/GitHub/mini-project-2/Home.py", line 49, in <module>
    getattr(module, ui_func_name)()
  File "/Users/choenamho/Documents/GitHub/mini-project-2/modules/inventory.py", line 147, in inventory_ui
    filtered_sorted = filtered.sort_values("재고변동").reset_index(drop=True)
TypeError: DataFrame.reset_index() got an unexpected keyword argument 'hide_index'

ERROR:root:Module modules.inventory에서 오류 발생: Traceback (most recent call last):
  File "/Users/choenamho/Documents/GitHub/mini-project-2/Home.py", line 49, in <module>
    getattr(module, ui_func_name)()
  File "/Users/choenamho/Documents/GitHub/mini-project-2/modules/inventory.py", line 132, in inventory_ui
    st.altair_chart(draw_inventory_chart(filtered), use_container_width=True)
NameError: name 'draw_inventory_chart' is not defined. Did you mean: 'draw_inventory_trend_chart'?

ERROR:root:Module modules.inventory에서 오류 발생: Traceback (most recent call last):
  File "/Users/choenamho/Documents/GitHub/mini-project-2/Home.py", line 49, in <module>
    getattr(module, ui_func_name)()
  File "/Users/choenamho/Documents/GitHub/mini-project-2/modules/inventory.py", line 132, in inventory_ui
    st.altair_chart(draw_inventory_chart(filtered), use_container_width=True)
NameError: name 'draw_inventory_chart' is not defined. Did you mean: 'draw_inventory_trend_chart'?

ERROR:root:Module modules.inventory에서 오류 발생: Traceback (most recent call last):
  File "/Users/choenamho/Documents/GitHub/mini-project-2/Home.py", line 49, in <module>
    getattr(module, ui_func_name)()
  File "/Users/choenamho/Documents/GitHub/mini-project-2/modules/inventory.py", line 134, in inventory_ui
    st.altair_chart(draw_inventory_chart(filtered), use_container_width=True)
  File "/Users/choenamho/Documents/GitHub/mini-project-2/modules/inventory.py", line 82, in draw_inventory_chart
    df = inventory_df.copy()
NameError: name 'inventory_df' is not defined. Did you mean: 'inventory_ui'?

ERROR:root:Module modules.inventory에서 오류 발생: Traceback (most recent call last):
  File "/Users/choenamho/Documents/GitHub/mini-project-2/Home.py", line 49, in <module>
    getattr(module, ui_func_name)()
  File "/Users/choenamho/Documents/GitHub/mini-project-2/modules/inventory.py", line 134, in inventory_ui
    st.altair_chart(draw_inventory_chart(filtered), use_container_width=True)
  File "/Users/choenamho/Documents/GitHub/mini-project-2/modules/inventory.py", line 82, in draw_inventory_chart
    df = inventory_df.copy()
NameError: name 'inventory_df' is not defined. Did you mean: 'inventory_ui'?

ERROR:root:Module modules.inventory에서 오류 발생: Traceback (most recent call last):
  File "/Users/choenamho/Documents/GitHub/mini-project-2/Home.py", line 48, in <module>
    module = __import__(mod_path, fromlist=[ui_func_name])
  File "/Users/choenamho/Documents/GitHub/mini-project-2/modules/inventory.py", line 79
    def draw_inventory_chart(filtered_df, , brand_sel):
                                          ^
SyntaxError: invalid syntax

ERROR:root:Module modules.inventory에서 오류 발생: Traceback (most recent call last):
  File "/Users/choenamho/Documents/GitHub/mini-project-2/Home.py", line 48, in <module>
    module = __import__(mod_path, fromlist=[ui_func_name])
  File "/Users/choenamho/Documents/GitHub/mini-project-2/modules/inventory.py", line 79
    def draw_inventory_chart(filtered_df, , brand_sel):
                                          ^
SyntaxError: invalid syntax

ERROR:root:Module modules.inventory에서 오류 발생: Traceback (most recent call last):
  File "/Users/choenamho/Documents/GitHub/mini-project-2/Home.py", line 49, in <module>
    getattr(module, ui_func_name)()
  File "/Users/choenamho/Documents/GitHub/mini-project-2/modules/inventory.py", line 134, in inventory_ui
    st.altair_chart(draw_inventory_chart(filtered), use_container_width=True)
TypeError: draw_inventory_chart() missing 1 required positional argument: 'brand_sel'

ERROR:root:Module modules.inventory에서 오류 발생: Traceback (most recent call last):
  File "/Users/choenamho/Documents/GitHub/mini-project-2/Home.py", line 49, in <module>
    getattr(module, ui_func_name)()
  File "/Users/choenamho/Documents/GitHub/mini-project-2/modules/inventory.py", line 134, in inventory_ui
    st.altair_chart(draw_inventory_chart(filtered), use_container_width=True)
TypeError: draw_inventory_chart() missing 1 required positional argument: 'brand_sel'

ERROR:root:Module modules.inventory에서 오류 발생: Traceback (most recent call last):
  File "/Users/choenamho/Documents/GitHub/mini-project-2/Home.py", line 49, in <module>
    getattr(module, ui_func_name)()
  File "/Users/choenamho/Documents/GitHub/mini-project-2/modules/inventory.py", line 132, in inventory_ui
    st.altair_chart(draw_inventory_chart(filtered), use_container_width=True)
NameError: name 'draw_inventory_chart' is not defined. Did you mean: 'draw_inventory_trend_chart'?

ERROR:root:Module modules.inventory에서 오류 발생: Traceback (most recent call last):
  File "/Users/choenamho/Documents/GitHub/mini-project-2/Home.py", line 49, in <module>
    getattr(module, ui_func_name)()
  File "/Users/choenamho/Documents/GitHub/mini-project-2/modules/inventory.py", line 132, in inventory_ui
    st.altair_chart(draw_inventory_chart(filtered), use_container_width=True)
NameError: name 'draw_inventory_chart' is not defined. Did you mean: 'draw_inventory_trend_chart'?

ERROR:root:Module modules.inventory에서 오류 발생: Traceback (most recent call last):
  File "/Users/choenamho/Documents/GitHub/mini-project-2/Home.py", line 49, in <module>
    getattr(module, ui_func_name)()
  File "/Users/choenamho/Documents/GitHub/mini-project-2/modules/inventory.py", line 141, in inventory_ui
    st.altair_chart(draw_inventory_chart(filtered), use_container_width=True)
NameError: name 'draw_inventory_chart' is not defined. Did you mean: 'draw_inventory_trend_chart'?

ERROR:root:Module modules.inventory에서 오류 발생: Traceback (most recent call last):
  File "/Users/choenamho/Documents/GitHub/mini-project-2/Home.py", line 49, in <module>
    getattr(module, ui_func_name)()
  File "/Users/choenamho/Documents/GitHub/mini-project-2/modules/inventory.py", line 141, in inventory_ui
    st.altair_chart(draw_inventory_chart(filtered), use_container_width=True)
NameError: name 'draw_inventory_chart' is not defined. Did you mean: 'draw_inventory_trend_chart'?

ERROR:root:Module modules.inventory에서 오류 발생: Traceback (most recent call last):
  File "/Users/choenamho/Documents/GitHub/mini-project-2/Home.py", line 49, in <module>
    getattr(module, ui_func_name)()
  File "/Users/choenamho/Documents/GitHub/mini-project-2/modules/inventory.py", line 137, in inventory_ui
    ㅡ
NameError: name 'ᅳ' is not defined

ERROR:root:Module modules.inventory에서 오류 발생: Traceback (most recent call last):
  File "/Users/choenamho/Documents/GitHub/mini-project-2/Home.py", line 49, in <module>
    getattr(module, ui_func_name)()
  File "/Users/choenamho/Documents/GitHub/mini-project-2/modules/inventory.py", line 137, in inventory_ui
    ㅡ
NameError: name 'ᅳ' is not defined

ERROR:root:Module modules.inventory에서 오류 발생: Traceback (most recent call last):
  File "/Users/choenamho/Documents/GitHub/mini-project-2/Home.py", line 49, in <module>
    getattr(module, ui_func_name)()
  File "/Users/choenamho/Documents/GitHub/mini-project-2/modules/inventory.py", line 137, in inventory_ui
    mark
NameError: name 'mark' is not defined

ERROR:root:Module modules.inventory에서 오류 발생: Traceback (most recent call last):
  File "/Users/choenamho/Documents/GitHub/mini-project-2/Home.py", line 49, in <module>
    getattr(module, ui_func_name)()
  File "/Users/choenamho/Documents/GitHub/mini-project-2/modules/inventory.py", line 137, in inventory_ui
    mark
NameError: name 'mark' is not defined

ERROR:root:Module modules.inventory에서 오류 발생: Traceback (most recent call last):
  File "/Users/choenamho/Documents/GitHub/mini-project-2/Home.py", line 49, in <module>
    getattr(module, ui_func_name)()
  File "/Users/choenamho/Documents/GitHub/mini-project-2/modules/inventory.py", line 137, in inventory_ui
    st,mar
NameError: name 'mar' is not defined. Did you mean: 'max'?

ERROR:root:Module modules.inventory에서 오류 발생: Traceback (most recent call last):
  File "/Users/choenamho/Documents/GitHub/mini-project-2/Home.py", line 49, in <module>
    getattr(module, ui_func_name)()
  File "/Users/choenamho/Documents/GitHub/mini-project-2/modules/inventory.py", line 137, in inventory_ui
    st,mark
NameError: name 'mark' is not defined

ERROR:root:Module modules.inventory에서 오류 발생: Traceback (most recent call last):
  File "/Users/choenamho/Documents/GitHub/mini-project-2/Home.py", line 49, in <module>
    getattr(module, ui_func_name)()
  File "/Users/choenamho/Documents/GitHub/mini-project-2/modules/inventory.py", line 137, in inventory_ui
    st,mark
NameError: name 'mark' is not defined

ERROR:root:Module modules.inventory에서 오류 발생: Traceback (most recent call last):
  File "/Users/choenamho/Documents/GitHub/mini-project-2/Home.py", line 49, in <module>
    getattr(module, ui_func_name)()
  File "/Users/choenamho/Documents/GitHub/mini-project-2/modules/inventory.py", line 137, in inventory_ui
    st,mark
NameError: name 'mark' is not defined

ERROR:root:Module modules.inventory에서 오류 발생: Traceback (most recent call last):
  File "/Users/choenamho/Documents/GitHub/mini-project-2/Home.py", line 49, in <module>
    getattr(module, ui_func_name)()
  File "/Users/choenamho/Documents/GitHub/mini-project-2/modules/inventory.py", line 137, in inventory_ui
    st,markd
NameError: name 'markd' is not defined

ERROR:root:Module modules.inventory에서 오류 발생: Traceback (most recent call last):
  File "/Users/choenamho/Documents/GitHub/mini-project-2/Home.py", line 49, in <module>
    getattr(module, ui_func_name)()
  File "/Users/choenamho/Documents/GitHub/mini-project-2/modules/inventory.py", line 137, in inventory_ui
    st,markd
NameError: name 'markd' is not defined

ERROR:root:Module modules.inventory에서 오류 발생: Traceback (most recent call last):
  File "/Users/choenamho/Documents/GitHub/mini-project-2/Home.py", line 49, in <module>
    getattr(module, ui_func_name)()
  File "/Users/choenamho/Documents/GitHub/mini-project-2/modules/inventory.py", line 137, in inventory_ui
    st.markd
AttributeError: module 'streamlit' has no attribute 'markd'

ERROR:root:Module modules.inventory에서 오류 발생: Traceback (most recent call last):
  File "/Users/choenamho/Documents/GitHub/mini-project-2/Home.py", line 49, in <module>
    getattr(module, ui_func_name)()
  File "/Users/choenamho/Documents/GitHub/mini-project-2/modules/inventory.py", line 137, in inventory_ui
    st.markd
AttributeError: module 'streamlit' has no attribute 'markd'

ERROR:root:Module modules.inventory에서 오류 발생: Traceback (most recent call last):
  File "/Users/choenamho/Documents/GitHub/mini-project-2/Home.py", line 49, in <module>
    getattr(module, ui_func_name)()
  File "/Users/choenamho/Documents/GitHub/mini-project-2/modules/inventory.py", line 137, in inventory_ui
    st.markdown()
  File "/Users/choenamho/hi/lib/python3.10/site-packages/streamlit/runtime/metrics_util.py", line 410, in wrapped_func
    result = non_optional_func(*args, **kwargs)
TypeError: MarkdownMixin.markdown() missing 1 required positional argument: 'body'

ERROR:root:Module modules.inventory에서 오류 발생: Traceback (most recent call last):
  File "/Users/choenamho/Documents/GitHub/mini-project-2/Home.py", line 49, in <module>
    getattr(module, ui_func_name)()
  File "/Users/choenamho/Documents/GitHub/mini-project-2/modules/inventory.py", line 137, in inventory_ui
    st.markdown()
  File "/Users/choenamho/hi/lib/python3.10/site-packages/streamlit/runtime/metrics_util.py", line 410, in wrapped_func
    result = non_optional_func(*args, **kwargs)
TypeError: MarkdownMixin.markdown() missing 1 required positional argument: 'body'

ERROR:root:Module modules.inventory에서 오류 발생: Traceback (most recent call last):
  File "/Users/choenamho/Documents/GitHub/mini-project-2/Home.py", line 48, in <module>
    module = __import__(mod_path, fromlist=[ui_func_name])
  File "/Users/choenamho/Documents/GitHub/mini-project-2/modules/inventory.py", line 136
    3    k3.metric("총 재고량", f"{stock:,} 대"); k4.metric("재고 부족 차종", f"{low} 종"); k5.metric("재고 과잉 차종", f"{high} 종")
         ^^
SyntaxError: invalid syntax

ERROR:root:Module modules.inventory에서 오류 발생: Traceback (most recent call last):
  File "/Users/choenamho/Documents/GitHub/mini-project-2/Home.py", line 48, in <module>
    module = __import__(mod_path, fromlist=[ui_func_name])
  File "/Users/choenamho/Documents/GitHub/mini-project-2/modules/inventory.py", line 136
    3    k3.metric("총 재고량", f"{stock:,} 대"); k4.metric("재고 부족 차종", f"{low} 종"); k5.metric("재고 과잉 차종", f"{high} 종")
         ^^
SyntaxError: invalid syntax

ERROR:root:Module modules.inventory에서 오류 발생: Traceback (most recent call last):
  File "/Users/choenamho/Documents/GitHub/mini-project-2/Home.py", line 48, in <module>
    module = __import__(mod_path, fromlist=[ui_func_name])
  File "/Users/choenamho/Documents/GitHub/mini-project-2/modules/inventory.py", line 131
    st.subheader("주 요 """"지 표")
                       ^
SyntaxError: unterminated triple-quoted string literal (detected at line 165)

ERROR:root:Module modules.inventory에서 오류 발생: Traceback (most recent call last):
  File "/Users/choenamho/Documents/GitHub/mini-project-2/Home.py", line 48, in <module>
    module = __import__(mod_path, fromlist=[ui_func_name])
  File "/Users/choenamho/Documents/GitHub/mini-project-2/modules/inventory.py", line 131
    st.subheader("주 요 """"지 표")
                       ^
SyntaxError: unterminated triple-quoted string literal (detected at line 165)

ERROR:root:Module modules.inventory에서 오류 발생: Traceback (most recent call last):
  File "/Users/choenamho/Documents/GitHub/mini-project-2/Home.py", line 48, in <module>
    module = __import__(mod_path, fromlist=[ui_func_name])
  File "/Users/choenamho/Documents/GitHub/mini-project-2/modules/inventory.py", line 131
    st.subheader("주 요 " """지 표")
                        ^
SyntaxError: unterminated triple-quoted string literal (detected at line 165)

ERROR:root:Module modules.inventory에서 오류 발생: Traceback (most recent call last):
  File "/Users/choenamho/Documents/GitHub/mini-project-2/Home.py", line 48, in <module>
    module = __import__(mod_path, fromlist=[ui_func_name])
  File "/Users/choenamho/Documents/GitHub/mini-project-2/modules/inventory.py", line 131
    st.subheader("주 요 " """지 표")
                        ^
SyntaxError: unterminated triple-quoted string literal (detected at line 165)

ERROR:root:Module modules.inventory에서 오류 발생: Traceback (most recent call last):
  File "/Users/choenamho/Documents/GitHub/mini-project-2/Home.py", line 48, in <module>
    module = __import__(mod_path, fromlist=[ui_func_name])
  File "/Users/choenamho/Documents/GitHub/mini-project-2/modules/inventory.py", line 131
    st.subheader("주 요 "+ """지 표")
                         ^
SyntaxError: unterminated triple-quoted string literal (detected at line 165)

ERROR:root:Module modules.inventory에서 오류 발생: Traceback (most recent call last):
  File "/Users/choenamho/Documents/GitHub/mini-project-2/Home.py", line 48, in <module>
    module = __import__(mod_path, fromlist=[ui_func_name])
  File "/Users/choenamho/Documents/GitHub/mini-project-2/modules/inventory.py", line 131
    st.subheader("주 요 "+ """지 표")
                         ^
SyntaxError: unterminated triple-quoted string literal (detected at line 165)

ERROR:root:Module modules.inventory에서 오류 발생: Traceback (most recent call last):
  File "/Users/choenamho/Documents/GitHub/mini-project-2/Home.py", line 49, in <module>
    getattr(module, ui_func_name)()
  File "/Users/choenamho/Documents/GitHub/mini-project-2/modules/inventory.py", line 141, in inventory_ui
    col1, col2, ol2= st.columns(2)
ValueError: not enough values to unpack (expected 3, got 2)

ERROR:root:Module modules.inventory에서 오류 발생: Traceback (most recent call last):
  File "/Users/choenamho/Documents/GitHub/mini-project-2/Home.py", line 49, in <module>
    getattr(module, ui_func_name)()
  File "/Users/choenamho/Documents/GitHub/mini-project-2/modules/inventory.py", line 141, in inventory_ui
    col1, col2, ol2= st.columns(2)
ValueError: not enough values to unpack (expected 3, got 2)

ERROR:root:Module modules.inventory에서 오류 발생: Traceback (most recent call last):
  File "/Users/choenamho/Documents/GitHub/mini-project-2/Home.py", line 49, in <module>
    getattr(module, ui_func_name)()
  File "/Users/choenamho/Documents/GitHub/mini-project-2/modules/inventory.py", line 141, in inventory_ui
    col1, col2, ol3= st.columns(2)
ValueError: not enough values to unpack (expected 3, got 2)

ERROR:root:Module modules.inventory에서 오류 발생: Traceback (most recent call last):
  File "/Users/choenamho/Documents/GitHub/mini-project-2/Home.py", line 49, in <module>
    getattr(module, ui_func_name)()
  File "/Users/choenamho/Documents/GitHub/mini-project-2/modules/inventory.py", line 141, in inventory_ui
    col1, col2, ol3= st.columns(2)
ValueError: not enough values to unpack (expected 3, got 2)

ERROR:root:Module modules.inventory에서 오류 발생: Traceback (most recent call last):
  File "/Users/choenamho/Documents/GitHub/mini-project-2/Home.py", line 49, in <module>
    getattr(module, ui_func_name)()
  File "/Users/choenamho/Documents/GitHub/mini-project-2/modules/inventory.py", line 141, in inventory_ui
    col1, col2, col3= st.columns(2)
ValueError: not enough values to unpack (expected 3, got 2)

ERROR:root:Module modules.inventory에서 오류 발생: Traceback (most recent call last):
  File "/Users/choenamho/Documents/GitHub/mini-project-2/Home.py", line 49, in <module>
    getattr(module, ui_func_name)()
  File "/Users/choenamho/Documents/GitHub/mini-project-2/modules/inventory.py", line 141, in inventory_ui
    col1, col2, col3= st.columns(2)
ValueError: not enough values to unpack (expected 3, got 2)

ERROR:root:Module modules.inventory에서 오류 발생: Traceback (most recent call last):
  File "/Users/choenamho/Documents/GitHub/mini-project-2/Home.py", line 49, in <module>
    getattr(module, ui_func_name)()
  File "/Users/choenamho/Documents/GitHub/mini-project-2/modules/inventory.py", line 141, in inventory_ui
    col1, col2, col3= st.columns()
  File "/Users/choenamho/hi/lib/python3.10/site-packages/streamlit/runtime/metrics_util.py", line 410, in wrapped_func
    result = non_optional_func(*args, **kwargs)
TypeError: LayoutsMixin.columns() missing 1 required positional argument: 'spec'

ERROR:root:Module modules.inventory에서 오류 발생: Traceback (most recent call last):
  File "/Users/choenamho/Documents/GitHub/mini-project-2/Home.py", line 49, in <module>
    getattr(module, ui_func_name)()
  File "/Users/choenamho/Documents/GitHub/mini-project-2/modules/inventory.py", line 141, in inventory_ui
    col1, col2, col3= st.columns()
  File "/Users/choenamho/hi/lib/python3.10/site-packages/streamlit/runtime/metrics_util.py", line 410, in wrapped_func
    result = non_optional_func(*args, **kwargs)
TypeError: LayoutsMixin.columns() missing 1 required positional argument: 'spec'

ERROR:root:Module modules.inventory에서 오류 발생: Traceback (most recent call last):
  File "/Users/choenamho/Documents/GitHub/mini-project-2/Home.py", line 49, in <module>
    getattr(module, ui_func_name)()
  File "/Users/choenamho/Documents/GitHub/mini-project-2/modules/inventory.py", line 141, in inventory_ui
    col1, col2, col3= st.columns([])
  File "/Users/choenamho/hi/lib/python3.10/site-packages/streamlit/runtime/metrics_util.py", line 410, in wrapped_func
    result = non_optional_func(*args, **kwargs)
  File "/Users/choenamho/hi/lib/python3.10/site-packages/streamlit/elements/layouts.py", line 341, in columns
    raise StreamlitInvalidColumnSpecError()
streamlit.errors.StreamlitInvalidColumnSpecError: The `spec` argument to `st.columns` must be either a positive integer (number of columns) or a list of positive numbers (width ratios of the columns). See [documentation](https://docs.streamlit.io/develop/api-reference/layout/st.columns) for more information.

ERROR:root:Module modules.inventory에서 오류 발생: Traceback (most recent call last):
  File "/Users/choenamho/Documents/GitHub/mini-project-2/Home.py", line 49, in <module>
    getattr(module, ui_func_name)()
  File "/Users/choenamho/Documents/GitHub/mini-project-2/modules/inventory.py", line 141, in inventory_ui
    col1, col2, col3= st.columns([])
  File "/Users/choenamho/hi/lib/python3.10/site-packages/streamlit/runtime/metrics_util.py", line 410, in wrapped_func
    result = non_optional_func(*args, **kwargs)
  File "/Users/choenamho/hi/lib/python3.10/site-packages/streamlit/elements/layouts.py", line 341, in columns
    raise StreamlitInvalidColumnSpecError()
streamlit.errors.StreamlitInvalidColumnSpecError: The `spec` argument to `st.columns` must be either a positive integer (number of columns) or a list of positive numbers (width ratios of the columns). See [documentation](https://docs.streamlit.io/develop/api-reference/layout/st.columns) for more information.

ERROR:root:Module modules.inventory에서 오류 발생: Traceback (most recent call last):
  File "/Users/choenamho/Documents/GitHub/mini-project-2/Home.py", line 48, in <module>
    module = __import__(mod_path, fromlist=[ui_func_name])
  File "/Users/choenamho/Documents/GitHub/mini-project-2/modules/inventory.py", line 160
    st.dataframe(filtered_sorted, use_container_width=True, hide_index=True)
IndentationError: unexpected indent

ERROR:root:Module modules.inventory에서 오류 발생: Traceback (most recent call last):
  File "/Users/choenamho/Documents/GitHub/mini-project-2/Home.py", line 48, in <module>
    module = __import__(mod_path, fromlist=[ui_func_name])
  File "/Users/choenamho/Documents/GitHub/mini-project-2/modules/inventory.py", line 160
    st.dataframe(filtered_sorted, use_container_width=True, hide_index=True)
IndentationError: unexpected indent

ERROR:root:Module modules.inventory에서 오류 발생: Traceback (most recent call last):
  File "/Users/choenamho/Documents/GitHub/mini-project-2/Home.py", line 49, in <module>
    getattr(module, ui_func_name)()
  File "/Users/choenamho/Documents/GitHub/mini-project-2/modules/inventory.py", line 159, in inventory_ui
    col1, col2, col3 = st.columns([1, 1])
ValueError: not enough values to unpack (expected 3, got 2)

ERROR:root:Module modules.inventory에서 오류 발생: Traceback (most recent call last):
  File "/Users/choenamho/Documents/GitHub/mini-project-2/Home.py", line 49, in <module>
    getattr(module, ui_func_name)()
  File "/Users/choenamho/Documents/GitHub/mini-project-2/modules/inventory.py", line 159, in inventory_ui
    col1, col2, col3 = st.columns([1, 1])
ValueError: not enough values to unpack (expected 3, got 2)

ERROR:root:Module modules.inventory에서 오류 발생: Traceback (most recent call last):
  File "/Users/choenamho/Documents/GitHub/mini-project-2/Home.py", line 49, in <module>
    getattr(module, ui_func_name)()
  File "/Users/choenamho/Documents/GitHub/mini-project-2/modules/inventory.py", line 158, in inventory_ui
    col1st.dataframe(filtered_sorted, use_container_width=True, hide_index=True)
NameError: name 'col1st' is not defined. Did you mean: 'col1'?

ERROR:root:Module modules.inventory에서 오류 발생: Traceback (most recent call last):
  File "/Users/choenamho/Documents/GitHub/mini-project-2/Home.py", line 49, in <module>
    getattr(module, ui_func_name)()
  File "/Users/choenamho/Documents/GitHub/mini-project-2/modules/inventory.py", line 158, in inventory_ui
    col1st.dataframe(filtered_sorted, use_container_width=True, hide_index=True)
NameError: name 'col1st' is not defined. Did you mean: 'col1'?

ERROR:root:Module modules.inventory에서 오류 발생: Traceback (most recent call last):
  File "/Users/choenamho/Documents/GitHub/mini-project-2/Home.py", line 49, in <module>
    getattr(module, ui_func_name)()
  File "/Users/choenamho/Documents/GitHub/mini-project-2/modules/inventory.py", line 158, in inventory_ui
    col1.st.dataframe(filtered_sorted, use_container_width=True, hide_index=True)
AttributeError: 'function' object has no attribute 'dataframe'

ERROR:root:Module modules.inventory에서 오류 발생: Traceback (most recent call last):
  File "/Users/choenamho/Documents/GitHub/mini-project-2/Home.py", line 49, in <module>
    getattr(module, ui_func_name)()
  File "/Users/choenamho/Documents/GitHub/mini-project-2/modules/inventory.py", line 158, in inventory_ui
    col1.st.dataframe(filtered_sorted, use_container_width=True, hide_index=True)
AttributeError: 'function' object has no attribute 'dataframe'

ERROR:root:Module modules.inventory에서 오류 발생: Traceback (most recent call last):
  File "/Users/choenamho/Documents/GitHub/mini-project-2/Home.py", line 49, in <module>
    getattr(module, ui_func_name)()
  File "/Users/choenamho/Documents/GitHub/mini-project-2/modules/inventory.py", line 158, in inventory_ui
    col1.st.dataframe(filtered_sorted, use_container_width=True, hide_index=True)
AttributeError: 'function' object has no attribute 'dataframe'

ERROR:root:Module modules.inventory에서 오류 발생: Traceback (most recent call last):
  File "/Users/choenamho/Documents/GitHub/mini-project-2/Home.py", line 49, in <module>
    getattr(module, ui_func_name)()
  File "/Users/choenamho/Documents/GitHub/mini-project-2/modules/inventory.py", line 158, in inventory_ui
    col1.st.dataframe(filtered_sorted, use_container_width=True, hide_index=True)
AttributeError: 'function' object has no attribute 'dataframe'

ERROR:root:Module modules.inventory에서 오류 발생: Traceback (most recent call last):
  File "/Users/choenamho/Documents/GitHub/mini-project-2/Home.py", line 49, in <module>
    getattr(module, ui_func_name)()
  File "/Users/choenamho/Documents/GitHub/mini-project-2/modules/inventory.py", line 158, in inventory_ui
    col1.st.dataframe(filtered_sorted, use_container_width=True, hide_index=True)
AttributeError: 'function' object has no attribute 'dataframe'

ERROR:root:Module modules.inventory에서 오류 발생: Traceback (most recent call last):
  File "/Users/choenamho/Documents/GitHub/mini-project-2/Home.py", line 49, in <module>
    getattr(module, ui_func_name)()
  File "/Users/choenamho/Documents/GitHub/mini-project-2/modules/inventory.py", line 158, in inventory_ui
    col1.st.dataframe(filtered_sorted, use_container_width=True, hide_index=True)
AttributeError: 'function' object has no attribute 'dataframe'

ERROR:root:Module modules.inventory에서 오류 발생: Traceback (most recent call last):
  File "/Users/choenamho/Documents/GitHub/mini-project-2/Home.py", line 48, in <module>
    module = __import__(mod_path, fromlist=[ui_func_name])
  File "/Users/choenamho/Documents/GitHub/mini-project-2/modules/inventory.py", line 160
    with
        ^
SyntaxError: invalid syntax

ERROR:root:Module modules.inventory에서 오류 발생: Traceback (most recent call last):
  File "/Users/choenamho/Documents/GitHub/mini-project-2/Home.py", line 48, in <module>
    module = __import__(mod_path, fromlist=[ui_func_name])
  File "/Users/choenamho/Documents/GitHub/mini-project-2/modules/inventory.py", line 160
    with 
         ^
SyntaxError: invalid syntax

ERROR:root:Module modules.inventory에서 오류 발생: Traceback (most recent call last):
  File "/Users/choenamho/Documents/GitHub/mini-project-2/Home.py", line 48, in <module>
    module = __import__(mod_path, fromlist=[ui_func_name])
  File "/Users/choenamho/Documents/GitHub/mini-project-2/modules/inventory.py", line 160
    with 
         ^
SyntaxError: invalid syntax

ERROR:root:Module modules.inventory에서 오류 발생: Traceback (most recent call last):
  File "/Users/choenamho/Documents/GitHub/mini-project-2/Home.py", line 48, in <module>
    module = __import__(mod_path, fromlist=[ui_func_name])
  File "/Users/choenamho/Documents/GitHub/mini-project-2/modules/inventory.py", line 160
    with 
         ^
SyntaxError: invalid syntax

ERROR:root:Module modules.inventory에서 오류 발생: Traceback (most recent call last):
  File "/Users/choenamho/Documents/GitHub/mini-project-2/Home.py", line 48, in <module>
    module = __import__(mod_path, fromlist=[ui_func_name])
  File "/Users/choenamho/Documents/GitHub/mini-project-2/modules/inventory.py", line 160
    with col
            ^
SyntaxError: expected ':'

ERROR:root:Module modules.inventory에서 오류 발생: Traceback (most recent call last):
  File "/Users/choenamho/Documents/GitHub/mini-project-2/Home.py", line 48, in <module>
    module = __import__(mod_path, fromlist=[ui_func_name])
  File "/Users/choenamho/Documents/GitHub/mini-project-2/modules/inventory.py", line 160
    with col
            ^
SyntaxError: expected ':'

ERROR:root:Module modules.inventory에서 오류 발생: Traceback (most recent call last):
  File "/Users/choenamho/Documents/GitHub/mini-project-2/Home.py", line 48, in <module>
    module = __import__(mod_path, fromlist=[ui_func_name])
  File "/Users/choenamho/Documents/GitHub/mini-project-2/modules/inventory.py", line 160
    with col2
             ^
SyntaxError: expected ':'

ERROR:root:Module modules.inventory에서 오류 발생: Traceback (most recent call last):
  File "/Users/choenamho/Documents/GitHub/mini-project-2/Home.py", line 48, in <module>
    module = __import__(mod_path, fromlist=[ui_func_name])
  File "/Users/choenamho/Documents/GitHub/mini-project-2/modules/inventory.py", line 160
    with col2
             ^
SyntaxError: expected ':'

ERROR:root:Module modules.inventory에서 오류 발생: Traceback (most recent call last):
  File "/Users/choenamho/Documents/GitHub/mini-project-2/Home.py", line 48, in <module>
    module = __import__(mod_path, fromlist=[ui_func_name])
  File "/Users/choenamho/Documents/GitHub/mini-project-2/modules/inventory.py", line 162
    with col2
IndentationError: unexpected indent

ERROR:root:Module modules.inventory에서 오류 발생: Traceback (most recent call last):
  File "/Users/choenamho/Documents/GitHub/mini-project-2/Home.py", line 48, in <module>
    module = __import__(mod_path, fromlist=[ui_func_name])
  File "/Users/choenamho/Documents/GitHub/mini-project-2/modules/inventory.py", line 162
    with col2
IndentationError: unexpected indent

ERROR:root:Module modules.inventory에서 오류 발생: Traceback (most recent call last):
  File "/Users/choenamho/Documents/GitHub/mini-project-2/Home.py", line 48, in <module>
    module = __import__(mod_path, fromlist=[ui_func_name])
  File "/Users/choenamho/Documents/GitHub/mini-project-2/modules/inventory.py", line 162
    with col2:
IndentationError: unexpected indent

ERROR:root:Module modules.inventory에서 오류 발생: Traceback (most recent call last):
  File "/Users/choenamho/Documents/GitHub/mini-project-2/Home.py", line 48, in <module>
    module = __import__(mod_path, fromlist=[ui_func_name])
  File "/Users/choenamho/Documents/GitHub/mini-project-2/modules/inventory.py", line 162
    with col2:
IndentationError: unexpected indent

ERROR:root:Module modules.inventory에서 오류 발생: Traceback (most recent call last):
  File "/Users/choenamho/Documents/GitHub/mini-project-2/Home.py", line 48, in <module>
    module = __import__(mod_path, fromlist=[ui_func_name])
  File "/Users/choenamho/Documents/GitHub/mini-project-2/modules/inventory.py", line 162
    with col2:
IndentationError: unexpected indent

ERROR:root:Module modules.inventory에서 오류 발생: Traceback (most recent call last):
  File "/Users/choenamho/Documents/GitHub/mini-project-2/Home.py", line 48, in <module>
    module = __import__(mod_path, fromlist=[ui_func_name])
  File "/Users/choenamho/Documents/GitHub/mini-project-2/modules/inventory.py", line 163
    col2.dataframe(top10[["브랜드", "차종", "연도", "재고변동"]], use_container_width=True, hide_index=True)
    ^^^^
IndentationError: expected an indented block after 'with' statement on line 162

ERROR:root:Module modules.inventory에서 오류 발생: Traceback (most recent call last):
  File "/Users/choenamho/Documents/GitHub/mini-project-2/Home.py", line 48, in <module>
    module = __import__(mod_path, fromlist=[ui_func_name])
  File "/Users/choenamho/Documents/GitHub/mini-project-2/modules/inventory.py", line 163
    col2.dataframe(top10[["브랜드", "차종", "연도", "재고변동"]], use_container_width=True, hide_index=True)
    ^^^^
IndentationError: expected an indented block after 'with' statement on line 162

ERROR:root:Module modules.inventory에서 오류 발생: Traceback (most recent call last):
  File "/Users/choenamho/Documents/GitHub/mini-project-2/Home.py", line 48, in <module>
    module = __import__(mod_path, fromlist=[ui_func_name])
  File "/Users/choenamho/Documents/GitHub/mini-project-2/modules/inventory.py", line 163
    col2.dataframe(top10[["브랜드", "차종", "연도", "재고변동"]], use_container_width=True, hide_index=True)
    ^^^^
IndentationError: expected an indented block after 'with' statement on line 162

ERROR:root:Module modules.inventory에서 오류 발생: Traceback (most recent call last):
  File "/Users/choenamho/Documents/GitHub/mini-project-2/Home.py", line 48, in <module>
    module = __import__(mod_path, fromlist=[ui_func_name])
  File "/Users/choenamho/Documents/GitHub/mini-project-2/modules/inventory.py", line 163
    col2.dataframe(top10[["브랜드", "차종", "연도", "재고변동"]], use_container_width=True, hide_index=True)
    ^^^^
IndentationError: expected an indented block after 'with' statement on line 162

ERROR:root:Module modules.inventory에서 오류 발생: Traceback (most recent call last):
  File "/Users/choenamho/Documents/GitHub/mini-project-2/Home.py", line 48, in <module>
    module = __import__(mod_path, fromlist=[ui_func_name])
  File "/Users/choenamho/Documents/GitHub/mini-project-2/modules/inventory.py", line 163
    col2.dataframe(top10[["브랜드", "차종", "연도", "재고변동"]], use_container_width=True, hide_index=True)
    ^^^^
IndentationError: expected an indented block after 'with' statement on line 162

ERROR:root:Module modules.inventory에서 오류 발생: Traceback (most recent call last):
  File "/Users/choenamho/Documents/GitHub/mini-project-2/Home.py", line 48, in <module>
    module = __import__(mod_path, fromlist=[ui_func_name])
  File "/Users/choenamho/Documents/GitHub/mini-project-2/modules/inventory.py", line 163
    col2.dataframe(top10[["브랜드", "차종", "연도", "재고변동"]], use_container_width=True, hide_index=True)
    ^^^^
IndentationError: expected an indented block after 'with' statement on line 162

ERROR:root:Module modules.inventory에서 오류 발생: Traceback (most recent call last):
  File "/Users/choenamho/Documents/GitHub/mini-project-2/Home.py", line 48, in <module>
    module = __import__(mod_path, fromlist=[ui_func_name])
  File "/Users/choenamho/Documents/GitHub/mini-project-2/modules/inventory.py", line 163
    col2.dataframe(top10[["브랜드", "차종", "연도", "재고변동"]], use_container_width=True, hide_index=True)
    ^^^^
IndentationError: expected an indented block after 'with' statement on line 162

ERROR:root:Module modules.inventory에서 오류 발생: Traceback (most recent call last):
  File "/Users/choenamho/Documents/GitHub/mini-project-2/Home.py", line 48, in <module>
    module = __import__(mod_path, fromlist=[ui_func_name])
  File "/Users/choenamho/Documents/GitHub/mini-project-2/modules/inventory.py", line 163
    col2.dataframe(top10[["브랜드", "차종", "연도", "재고변동"]], use_container_width=True, hide_index=True)
    ^^^^
IndentationError: expected an indented block after 'with' statement on line 162

ERROR:root:Module modules.inventory에서 오류 발생: Traceback (most recent call last):
  File "/Users/choenamho/Documents/GitHub/mini-project-2/Home.py", line 48, in <module>
    module = __import__(mod_path, fromlist=[ui_func_name])
  File "/Users/choenamho/Documents/GitHub/mini-project-2/modules/inventory.py", line 159
    col1.dataframe(filtered_sorted, use_container_width=True, hide_index=True)
IndentationError: unexpected indent

ERROR:root:Module modules.inventory에서 오류 발생: Traceback (most recent call last):
  File "/Users/choenamho/Documents/GitHub/mini-project-2/Home.py", line 48, in <module>
    module = __import__(mod_path, fromlist=[ui_func_name])
  File "/Users/choenamho/Documents/GitHub/mini-project-2/modules/inventory.py", line 159
    col1.dataframe(filtered_sorted, use_container_width=True, hide_index=True)
IndentationError: unexpected indent

ERROR:root:Module modules.inventory에서 오류 발생: Traceback (most recent call last):
  File "/Users/choenamho/Documents/GitHub/mini-project-2/Home.py", line 48, in <module>
    module = __import__(mod_path, fromlist=[ui_func_name])
  File "/Users/choenamho/Documents/GitHub/mini-project-2/modules/inventory.py", line 159
    with col2:
IndentationError: unexpected indent

ERROR:root:Module modules.inventory에서 오류 발생: Traceback (most recent call last):
  File "/Users/choenamho/Documents/GitHub/mini-project-2/Home.py", line 48, in <module>
    module = __import__(mod_path, fromlist=[ui_func_name])
  File "/Users/choenamho/Documents/GitHub/mini-project-2/modules/inventory.py", line 159
    with col2:
IndentationError: unexpected indent

ERROR:root:Module modules.inventory에서 오류 발생: Traceback (most recent call last):
  File "/Users/choenamho/Documents/GitHub/mini-project-2/Home.py", line 48, in <module>
    module = __import__(mod_path, fromlist=[ui_func_name])
  File "/Users/choenamho/Documents/GitHub/mini-project-2/modules/inventory.py", line 159
    with col1:
IndentationError: unexpected indent

ERROR:root:Module modules.inventory에서 오류 발생: Traceback (most recent call last):
  File "/Users/choenamho/Documents/GitHub/mini-project-2/Home.py", line 48, in <module>
    module = __import__(mod_path, fromlist=[ui_func_name])
  File "/Users/choenamho/Documents/GitHub/mini-project-2/modules/inventory.py", line 159
    with col1:
IndentationError: unexpected indent

ERROR:root:Module modules.inventory에서 오류 발생: Traceback (most recent call last):
  File "/Users/choenamho/Documents/GitHub/mini-project-2/Home.py", line 48, in <module>
    module = __import__(mod_path, fromlist=[ui_func_name])
  File "/Users/choenamho/Documents/GitHub/mini-project-2/modules/inventory.py", line 161
    col1.dataframe(filtered_sorted, use_container_width=True, hide_index=True)
    ^^^^
IndentationError: expected an indented block after 'with' statement on line 160

ERROR:root:Module modules.inventory에서 오류 발생: Traceback (most recent call last):
  File "/Users/choenamho/Documents/GitHub/mini-project-2/Home.py", line 48, in <module>
    module = __import__(mod_path, fromlist=[ui_func_name])
  File "/Users/choenamho/Documents/GitHub/mini-project-2/modules/inventory.py", line 161
    col1.dataframe(filtered_sorted, use_container_width=True, hide_index=True)
    ^^^^
IndentationError: expected an indented block after 'with' statement on line 160

ERROR:root:Module modules.inventory에서 오류 발생: Traceback (most recent call last):
  File "/Users/choenamho/Documents/GitHub/mini-project-2/Home.py", line 48, in <module>
    module = __import__(mod_path, fromlist=[ui_func_name])
  File "/Users/choenamho/Documents/GitHub/mini-project-2/modules/inventory.py", line 165
    with col2:
    ^^^^
IndentationError: expected an indented block after 'with' statement on line 164

ERROR:root:Module modules.inventory에서 오류 발생: Traceback (most recent call last):
  File "/Users/choenamho/Documents/GitHub/mini-project-2/Home.py", line 48, in <module>
    module = __import__(mod_path, fromlist=[ui_func_name])
  File "/Users/choenamho/Documents/GitHub/mini-project-2/modules/inventory.py", line 165
    with col2:
    ^^^^
IndentationError: expected an indented block after 'with' statement on line 164

ERROR:root:Module modules.inventory에서 오류 발생: Traceback (most recent call last):
  File "/Users/choenamho/Documents/GitHub/mini-project-2/Home.py", line 48, in <module>
    module = __import__(mod_path, fromlist=[ui_func_name])
  File "/Users/choenamho/Documents/GitHub/mini-project-2/modules/inventory.py", line 165
    with col2:
    ^^^^
IndentationError: expected an indented block after 'with' statement on line 164

ERROR:root:Module modules.inventory에서 오류 발생: Traceback (most recent call last):
  File "/Users/choenamho/Documents/GitHub/mini-project-2/Home.py", line 48, in <module>
    module = __import__(mod_path, fromlist=[ui_func_name])
  File "/Users/choenamho/Documents/GitHub/mini-project-2/modules/inventory.py", line 165
    with col2:
    ^^^^
IndentationError: expected an indented block after 'with' statement on line 164

ERROR:root:Module modules.inventory에서 오류 발생: Traceback (most recent call last):
  File "/Users/choenamho/Documents/GitHub/mini-project-2/Home.py", line 48, in <module>
    module = __import__(mod_path, fromlist=[ui_func_name])
  File "/Users/choenamho/Documents/GitHub/mini-project-2/modules/inventory.py", line 160
    with st.container():
IndentationError: unexpected indent

ERROR:root:Module modules.inventory에서 오류 발생: Traceback (most recent call last):
  File "/Users/choenamho/Documents/GitHub/mini-project-2/Home.py", line 48, in <module>
    module = __import__(mod_path, fromlist=[ui_func_name])
  File "/Users/choenamho/Documents/GitHub/mini-project-2/modules/inventory.py", line 160
    with st.container():
IndentationError: unexpected indent

ERROR:root:Module modules.inventory에서 오류 발생: Traceback (most recent call last):
  File "/Users/choenamho/Documents/GitHub/mini-project-2/Home.py", line 48, in <module>
    module = __import__(mod_path, fromlist=[ui_func_name])
  File "/Users/choenamho/Documents/GitHub/mini-project-2/modules/inventory.py", line 162
    st.subheader("필터 결과 상세 데이터")
    ^^
IndentationError: expected an indented block after 'with' statement on line 161

ERROR:root:Module modules.inventory에서 오류 발생: Traceback (most recent call last):
  File "/Users/choenamho/Documents/GitHub/mini-project-2/Home.py", line 48, in <module>
    module = __import__(mod_path, fromlist=[ui_func_name])
  File "/Users/choenamho/Documents/GitHub/mini-project-2/modules/inventory.py", line 162
    st.subheader("필터 결과 상세 데이터")
    ^^
IndentationError: expected an indented block after 'with' statement on line 161

ERROR:root:Module modules.inventory에서 오류 발생: Traceback (most recent call last):
  File "/Users/choenamho/Documents/GitHub/mini-project-2/Home.py", line 48, in <module>
    module = __import__(mod_path, fromlist=[ui_func_name])
  File "/Users/choenamho/Documents/GitHub/mini-project-2/modules/inventory.py", line 162
    st.subheader("필터 결과 상세 데이터")
    ^^
IndentationError: expected an indented block after 'with' statement on line 161

ERROR:root:Module modules.inventory에서 오류 발생: Traceback (most recent call last):
  File "/Users/choenamho/Documents/GitHub/mini-project-2/Home.py", line 48, in <module>
    module = __import__(mod_path, fromlist=[ui_func_name])
  File "/Users/choenamho/Documents/GitHub/mini-project-2/modules/inventory.py", line 162
    st.subheader("필터 결과 상세 데이터")
    ^^
IndentationError: expected an indented block after 'with' statement on line 161

ERROR:root:Module modules.inventory에서 오류 발생: Traceback (most recent call last):
  File "/Users/choenamho/Documents/GitHub/mini-project-2/Home.py", line 48, in <module>
    module = __import__(mod_path, fromlist=[ui_func_name])
  File "/Users/choenamho/Documents/GitHub/mini-project-2/modules/inventory.py", line 163
    col1.dataframe(filtered_sorted, use_container_width=True, hide_index=True)
    ^^^^
IndentationError: expected an indented block after 'with' statement on line 161

ERROR:root:Module modules.inventory에서 오류 발생: Traceback (most recent call last):
  File "/Users/choenamho/Documents/GitHub/mini-project-2/Home.py", line 48, in <module>
    module = __import__(mod_path, fromlist=[ui_func_name])
  File "/Users/choenamho/Documents/GitHub/mini-project-2/modules/inventory.py", line 163
    col1.dataframe(filtered_sorted, use_container_width=True, hide_index=True)
    ^^^^
IndentationError: expected an indented block after 'with' statement on line 161

ERROR:root:Module modules.inventory에서 오류 발생: Traceback (most recent call last):
  File "/Users/choenamho/Documents/GitHub/mini-project-2/Home.py", line 48, in <module>
    module = __import__(mod_path, fromlist=[ui_func_name])
  File "/Users/choenamho/Documents/GitHub/mini-project-2/modules/inventory.py", line 164
    col1.dataframe(filtered_sorted, use_container_width=True, hide_index=True)
    ^^^^
IndentationError: expected an indented block after 'with' statement on line 162

ERROR:root:Module modules.inventory에서 오류 발생: Traceback (most recent call last):
  File "/Users/choenamho/Documents/GitHub/mini-project-2/Home.py", line 48, in <module>
    module = __import__(mod_path, fromlist=[ui_func_name])
  File "/Users/choenamho/Documents/GitHub/mini-project-2/modules/inventory.py", line 164
    col1.dataframe(filtered_sorted, use_container_width=True, hide_index=True)
    ^^^^
IndentationError: expected an indented block after 'with' statement on line 162

ERROR:root:Module modules.inventory에서 오류 발생: Traceback (most recent call last):
  File "/Users/choenamho/Documents/GitHub/mini-project-2/Home.py", line 48, in <module>
    module = __import__(mod_path, fromlist=[ui_func_name])
  File "/Users/choenamho/Documents/GitHub/mini-project-2/modules/inventory.py", line 163
    col1.dataframe(filtered_sorted, use_container_width=True, hide_index=True)
    ^^^^
IndentationError: expected an indented block after 'with' statement on line 162

ERROR:root:Module modules.inventory에서 오류 발생: Traceback (most recent call last):
  File "/Users/choenamho/Documents/GitHub/mini-project-2/Home.py", line 48, in <module>
    module = __import__(mod_path, fromlist=[ui_func_name])
  File "/Users/choenamho/Documents/GitHub/mini-project-2/modules/inventory.py", line 163
    col1.dataframe(filtered_sorted, use_container_width=True, hide_index=True)
    ^^^^
IndentationError: expected an indented block after 'with' statement on line 162

ERROR:root:Module modules.inventory에서 오류 발생: Traceback (most recent call last):
  File "/Users/choenamho/Documents/GitHub/mini-project-2/Home.py", line 49, in <module>
    getattr(module, ui_func_name)()
  File "/Users/choenamho/Documents/GitHub/mini-project-2/modules/inventory.py", line 163, in inventory_ui
    dataframe(filtered_sorted, use_container_width=True, hide_index=True)
NameError: name 'dataframe' is not defined

ERROR:root:Module modules.inventory에서 오류 발생: Traceback (most recent call last):
  File "/Users/choenamho/Documents/GitHub/mini-project-2/Home.py", line 49, in <module>
    getattr(module, ui_func_name)()
  File "/Users/choenamho/Documents/GitHub/mini-project-2/modules/inventory.py", line 163, in inventory_ui
    dataframe(filtered_sorted, use_container_width=True, hide_index=True)
NameError: name 'dataframe' is not defined

ERROR:root:Module modules.inventory에서 오류 발생: Traceback (most recent call last):
  File "/Users/choenamho/Documents/GitHub/mini-project-2/Home.py", line 49, in <module>
    getattr(module, ui_func_name)()
  File "/Users/choenamho/Documents/GitHub/mini-project-2/modules/inventory.py", line 163, in inventory_ui
    dataframe(filtered_sorted, use_container_width=True, hide_index=True)
NameError: name 'dataframe' is not defined

ERROR:root:Module modules.inventory에서 오류 발생: Traceback (most recent call last):
  File "/Users/choenamho/Documents/GitHub/mini-project-2/Home.py", line 49, in <module>
    getattr(module, ui_func_name)()
  File "/Users/choenamho/Documents/GitHub/mini-project-2/modules/inventory.py", line 163, in inventory_ui
    dataframe(filtered_sorted, use_container_width=True, hide_index=True)
NameError: name 'dataframe' is not defined

ERROR:root:Module modules.inventory에서 오류 발생: Traceback (most recent call last):
  File "/Users/choenamho/Documents/GitHub/mini-project-2/Home.py", line 49, in <module>
    getattr(module, ui_func_name)()
  File "/Users/choenamho/Documents/GitHub/mini-project-2/modules/inventory.py", line 163, in inventory_ui
    dataframe(filtered_sorted, use_container_width=True, hide_index=True)
NameError: name 'dataframe' is not defined

ERROR:root:Module modules.inventory에서 오류 발생: Traceback (most recent call last):
  File "/Users/choenamho/Documents/GitHub/mini-project-2/Home.py", line 49, in <module>
    getattr(module, ui_func_name)()
  File "/Users/choenamho/Documents/GitHub/mini-project-2/modules/inventory.py", line 163, in inventory_ui
    dataframe(filtered_sorted, use_container_width=True, hide_index=True)
NameError: name 'dataframe' is not defined

ERROR:root:Module modules.inventory에서 오류 발생: Traceback (most recent call last):
  File "/Users/choenamho/Documents/GitHub/mini-project-2/Home.py", line 49, in <module>
    getattr(module, ui_func_name)()
  File "/Users/choenamho/Documents/GitHub/mini-project-2/modules/inventory.py", line 163, in inventory_ui
    dataframe(filtered_sorted, use_container_width=True, hide_index=True)
NameError: name 'dataframe' is not defined

ERROR:root:Module modules.inventory에서 오류 발생: Traceback (most recent call last):
  File "/Users/choenamho/Documents/GitHub/mini-project-2/Home.py", line 49, in <module>
    getattr(module, ui_func_name)()
  File "/Users/choenamho/Documents/GitHub/mini-project-2/modules/inventory.py", line 163, in inventory_ui
    dataframe(filtered_sorted, use_container_width=True, hide_index=True)
NameError: name 'dataframe' is not defined

ERROR:root:Module modules.inventory에서 오류 발생: Traceback (most recent call last):
  File "/Users/choenamho/Documents/GitHub/mini-project-2/Home.py", line 48, in <module>
    module = __import__(mod_path, fromlist=[ui_func_name])
  File "/Users/choenamho/Documents/GitHub/mini-project-2/modules/inventory.py", line 160
    with st.container():
    ^^^^
IndentationError: expected an indented block after 'with' statement on line 159

ERROR:root:Module modules.inventory에서 오류 발생: Traceback (most recent call last):
  File "/Users/choenamho/Documents/GitHub/mini-project-2/Home.py", line 48, in <module>
    module = __import__(mod_path, fromlist=[ui_func_name])
  File "/Users/choenamho/Documents/GitHub/mini-project-2/modules/inventory.py", line 160
    with st.container():
    ^^^^
IndentationError: expected an indented block after 'with' statement on line 159

ERROR:root:Module modules.inventory에서 오류 발생: Traceback (most recent call last):
  File "/Users/choenamho/Documents/GitHub/mini-project-2/Home.py", line 48, in <module>
    module = __import__(mod_path, fromlist=[ui_func_name])
  File "/Users/choenamho/Documents/GitHub/mini-project-2/modules/inventory.py", line 169
    st.dataframe(top10[["브랜드", "차종", "연도", "재고변동"]], use_container_width=True, hide_index=True)
IndentationError: unexpected indent

ERROR:root:Module modules.inventory에서 오류 발생: Traceback (most recent call last):
  File "/Users/choenamho/Documents/GitHub/mini-project-2/Home.py", line 48, in <module>
    module = __import__(mod_path, fromlist=[ui_func_name])
  File "/Users/choenamho/Documents/GitHub/mini-project-2/modules/inventory.py", line 169
    st.dataframe(top10[["브랜드", "차종", "연도", "재고변동"]], use_container_width=True, hide_index=True)
IndentationError: unexpected indent

ERROR:root:Module modules.inventory에서 오류 발생: Traceback (most recent call last):
  File "/Users/choenamho/Documents/GitHub/mini-project-2/Home.py", line 48, in <module>
    module = __import__(mod_path, fromlist=[ui_func_name])
  File "/Users/choenamho/Documents/GitHub/mini-project-2/modules/inventory.py", line 168
    st.subheader("재고 Top/Bottom 차종")
    ^^
IndentationError: expected an indented block after 'with' statement on line 167

ERROR:root:Module modules.inventory에서 오류 발생: Traceback (most recent call last):
  File "/Users/choenamho/Documents/GitHub/mini-project-2/Home.py", line 48, in <module>
    module = __import__(mod_path, fromlist=[ui_func_name])
  File "/Users/choenamho/Documents/GitHub/mini-project-2/modules/inventory.py", line 168
    st.subheader("재고 Top/Bottom 차종")
    ^^
IndentationError: expected an indented block after 'with' statement on line 167

ERROR:root:Module modules.inventory에서 오류 발생: Traceback (most recent call last):
  File "/Users/choenamho/Documents/GitHub/mini-project-2/Home.py", line 49, in <module>
    getattr(module, ui_func_name)()
  File "/Users/choenamho/Documents/GitHub/mini-project-2/modules/inventory.py", line 110, in inventory_ui
    col1, col2, col3,col3= st.columns([4, 1,1])
ValueError: not enough values to unpack (expected 4, got 3)

ERROR:root:Module modules.inventory에서 오류 발생: Traceback (most recent call last):
  File "/Users/choenamho/Documents/GitHub/mini-project-2/Home.py", line 49, in <module>
    getattr(module, ui_func_name)()
  File "/Users/choenamho/Documents/GitHub/mini-project-2/modules/inventory.py", line 110, in inventory_ui
    col1, col2, col3,col3= st.columns([4, 1,1])
ValueError: not enough values to unpack (expected 4, got 3)

ERROR:root:Module modules.inventory에서 오류 발생: Traceback (most recent call last):
  File "/Users/choenamho/Documents/GitHub/mini-project-2/Home.py", line 48, in <module>
    module = __import__(mod_path, fromlist=[ui_func_name])
  File "/Users/choenamho/Documents/GitHub/mini-project-2/modules/inventory.py", line 114
    st.subheader("오른쪽 정보")
    ^^
IndentationError: expected an indented block after 'with' statement on line 113

ERROR:root:Module modules.inventory에서 오류 발생: Traceback (most recent call last):
  File "/Users/choenamho/Documents/GitHub/mini-project-2/Home.py", line 48, in <module>
    module = __import__(mod_path, fromlist=[ui_func_name])
  File "/Users/choenamho/Documents/GitHub/mini-project-2/modules/inventory.py", line 114
    st.subheader("오른쪽 정보")
    ^^
IndentationError: expected an indented block after 'with' statement on line 113

ERROR:root:Module modules.inventory에서 오류 발생: Traceback (most recent call last):
  File "/Users/choenamho/Documents/GitHub/mini-project-2/Home.py", line 48, in <module>
    module = __import__(mod_path, fromlist=[ui_func_name])
  File "/Users/choenamho/Documents/GitHub/mini-project-2/modules/inventory.py", line 114
    st.subheader("오른쪽 정보")
    ^^
IndentationError: expected an indented block after 'with' statement on line 113

ERROR:root:Module modules.inventory에서 오류 발생: Traceback (most recent call last):
  File "/Users/choenamho/Documents/GitHub/mini-project-2/Home.py", line 48, in <module>
    module = __import__(mod_path, fromlist=[ui_func_name])
  File "/Users/choenamho/Documents/GitHub/mini-project-2/modules/inventory.py", line 114
    st.subheader("오른쪽 정보")
    ^^
IndentationError: expected an indented block after 'with' statement on line 113

ERROR:root:Module modules.inventory에서 오류 발생: Traceback (most recent call last):
  File "/Users/choenamho/Documents/GitHub/mini-project-2/Home.py", line 48, in <module>
    module = __import__(mod_path, fromlist=[ui_func_name])
  File "/Users/choenamho/Documents/GitHub/mini-project-2/modules/inventory.py", line 113, in <module>
    with col2:
NameError: name 'col2' is not defined

ERROR:root:Module modules.inventory에서 오류 발생: Traceback (most recent call last):
  File "/Users/choenamho/Documents/GitHub/mini-project-2/Home.py", line 48, in <module>
    module = __import__(mod_path, fromlist=[ui_func_name])
  File "/Users/choenamho/Documents/GitHub/mini-project-2/modules/inventory.py", line 113, in <module>
    with col2:
NameError: name 'col2' is not defined

ERROR:root:Module modules.inventory에서 오류 발생: Traceback (most recent call last):
  File "/Users/choenamho/Documents/GitHub/mini-project-2/Home.py", line 48, in <module>
    module = __import__(mod_path, fromlist=[ui_func_name])
  File "/Users/choenamho/Documents/GitHub/mini-project-2/modules/inventory.py", line 140
    col1, col2, = st.columns(2)
IndentationError: unexpected indent

ERROR:root:Module modules.inventory에서 오류 발생: Traceback (most recent call last):
  File "/Users/choenamho/Documents/GitHub/mini-project-2/Home.py", line 48, in <module>
    module = __import__(mod_path, fromlist=[ui_func_name])
  File "/Users/choenamho/Documents/GitHub/mini-project-2/modules/inventory.py", line 140
    col1, col2, = st.columns(2)
IndentationError: unexpected indent

ERROR:root:Module modules.inventory에서 오류 발생: Traceback (most recent call last):
  File "/Users/choenamho/Documents/GitHub/mini-project-2/Home.py", line 49, in <module>
    getattr(module, ui_func_name)()
  File "/Users/choenamho/Documents/GitHub/mini-project-2/modules/inventory.py", line 144, in inventory_ui
    st.altair_chart(draw_inventory_distribution_chart(filtered), use_container_width=True)
NameError: name 'filtered' is not defined. Did you mean: 'filter'?

ERROR:root:Module modules.inventory에서 오류 발생: Traceback (most recent call last):
  File "/Users/choenamho/Documents/GitHub/mini-project-2/Home.py", line 49, in <module>
    getattr(module, ui_func_name)()
  File "/Users/choenamho/Documents/GitHub/mini-project-2/modules/inventory.py", line 144, in inventory_ui
    st.altair_chart(draw_inventory_distribution_chart(filtered), use_container_width=True)
NameError: name 'filtered' is not defined. Did you mean: 'filter'?

ERROR:root:Module modules.inventory에서 오류 발생: Traceback (most recent call last):
  File "/Users/choenamho/Documents/GitHub/mini-project-2/Home.py", line 48, in <module>
    module = __import__(mod_path, fromlist=[ui_func_name])
  File "/Users/choenamho/Documents/GitHub/mini-project-2/modules/inventory.py", line 140
    col1, col2, = st.columns(2)
IndentationError: unexpected indent

ERROR:root:Module modules.inventory에서 오류 발생: Traceback (most recent call last):
  File "/Users/choenamho/Documents/GitHub/mini-project-2/Home.py", line 48, in <module>
    module = __import__(mod_path, fromlist=[ui_func_name])
  File "/Users/choenamho/Documents/GitHub/mini-project-2/modules/inventory.py", line 140
    col1, col2, = st.columns(2)
IndentationError: unexpected indent

ERROR:root:Module modules.inventory에서 오류 발생: Traceback (most recent call last):
  File "/Users/choenamho/Documents/GitHub/mini-project-2/Home.py", line 48, in <module>
    module = __import__(mod_path, fromlist=[ui_func_name])
  File "/Users/choenamho/Documents/GitHub/mini-project-2/modules/inventory.py", line 114
    st.markdown("<h2 style='text-align:center;'>|</h2>", unsafe_allow_html=True)
    ^^
IndentationError: expected an indented block after 'with' statement on line 113

ERROR:root:Module modules.inventory에서 오류 발생: Traceback (most recent call last):
  File "/Users/choenamho/Documents/GitHub/mini-project-2/Home.py", line 48, in <module>
    module = __import__(mod_path, fromlist=[ui_func_name])
  File "/Users/choenamho/Documents/GitHub/mini-project-2/modules/inventory.py", line 114
    st.markdown("<h2 style='text-align:center;'>|</h2>", unsafe_allow_html=True)
    ^^
IndentationError: expected an indented block after 'with' statement on line 113

ERROR:root:Module modules.inventory에서 오류 발생: Traceback (most recent call last):
  File "/Users/choenamho/Documents/GitHub/mini-project-2/Home.py", line 48, in <module>
    module = __import__(mod_path, fromlist=[ui_func_name])
  File "/Users/choenamho/Documents/GitHub/mini-project-2/modules/inventory.py", line 114
    st.markdown("<h2 style='text-align:center;'>|</h2>", unsafe_allow_html=True)
IndentationError: expected an indented block after 'with' statement on line 113

ERROR:root:Module modules.inventory에서 오류 발생: Traceback (most recent call last):
  File "/Users/choenamho/Documents/GitHub/mini-project-2/Home.py", line 48, in <module>
    module = __import__(mod_path, fromlist=[ui_func_name])
  File "/Users/choenamho/Documents/GitHub/mini-project-2/modules/inventory.py", line 114
    st.markdown("<h2 style='text-align:center;'>|</h2>", unsafe_allow_html=True)
IndentationError: expected an indented block after 'with' statement on line 113

ERROR:root:Module modules.inventory에서 오류 발생: Traceback (most recent call last):
  File "/Users/choenamho/Documents/GitHub/mini-project-2/Home.py", line 48, in <module>
    module = __import__(mod_path, fromlist=[ui_func_name])
  File "/Users/choenamho/Documents/GitHub/mini-project-2/modules/inventory.py", line 155
    col1, col2, = st.columns(2)
IndentationError: unexpected indent

ERROR:root:Module modules.inventory에서 오류 발생: Traceback (most recent call last):
  File "/Users/choenamho/Documents/GitHub/mini-project-2/Home.py", line 48, in <module>
    module = __import__(mod_path, fromlist=[ui_func_name])
  File "/Users/choenamho/Documents/GitHub/mini-project-2/modules/inventory.py", line 155
    col1, col2, = st.columns(2)
IndentationError: unexpected indent

ERROR:root:Module modules.inventory에서 오류 발생: Traceback (most recent call last):
  File "/Users/choenamho/Documents/GitHub/mini-project-2/Home.py", line 48, in <module>
    module = __import__(mod_path, fromlist=[ui_func_name])
  File "/Users/choenamho/Documents/GitHub/mini-project-2/modules/inventory.py", line 122, in <module>
    brand_list = ["전체"] + inventory_df["브랜드"].dropna().unique().tolist()
NameError: name 'inventory_df' is not defined. Did you mean: 'inventory_ui'?

ERROR:root:Module modules.inventory에서 오류 발생: Traceback (most recent call last):
  File "/Users/choenamho/Documents/GitHub/mini-project-2/Home.py", line 48, in <module>
    module = __import__(mod_path, fromlist=[ui_func_name])
  File "/Users/choenamho/Documents/GitHub/mini-project-2/modules/inventory.py", line 122, in <module>
    brand_list = ["전체"] + inventory_df["브랜드"].dropna().unique().tolist()
NameError: name 'inventory_df' is not defined. Did you mean: 'inventory_ui'?

ERROR:root:Module modules.inventory에서 오류 발생: Traceback (most recent call last):
  File "/Users/choenamho/Documents/GitHub/mini-project-2/Home.py", line 48, in <module>
    module = __import__(mod_path, fromlist=[ui_func_name])
  File "/Users/choenamho/Documents/GitHub/mini-project-2/modules/inventory.py", line 114
    col1, col2, col3 = st.columns([4, 1.5, 1.5])
IndentationError: unexpected indent

ERROR:root:Module modules.inventory에서 오류 발생: Traceback (most recent call last):
  File "/Users/choenamho/Documents/GitHub/mini-project-2/Home.py", line 48, in <module>
    module = __import__(mod_path, fromlist=[ui_func_name])
  File "/Users/choenamho/Documents/GitHub/mini-project-2/modules/inventory.py", line 114
    col1, col2, col3 = st.columns([4, 1.5, 1.5])
IndentationError: unexpected indent

ERROR:root:Module modules.inventory에서 오류 발생: Traceback (most recent call last):
  File "/Users/choenamho/Documents/GitHub/mini-project-2/Home.py", line 48, in <module>
    module = __import__(mod_path, fromlist=[ui_func_name])
  File "/Users/choenamho/Documents/GitHub/mini-project-2/modules/inventory.py", line 114
    col1, col2, col3 = st.columns([4, 1.5, 1.5])
IndentationError: unexpected indent

ERROR:root:Module modules.inventory에서 오류 발생: Traceback (most recent call last):
  File "/Users/choenamho/Documents/GitHub/mini-project-2/Home.py", line 48, in <module>
    module = __import__(mod_path, fromlist=[ui_func_name])
  File "/Users/choenamho/Documents/GitHub/mini-project-2/modules/inventory.py", line 114
    col1, col2, col3 = st.columns([4, 1.5, 1.5])
IndentationError: unexpected indent

ERROR:root:Module modules.inventory에서 오류 발생: Traceback (most recent call last):
  File "/Users/choenamho/Documents/GitHub/mini-project-2/Home.py", line 48, in <module>
    module = __import__(mod_path, fromlist=[ui_func_name])
  File "/Users/choenamho/Documents/GitHub/mini-project-2/modules/inventory.py", line 114
    col1, col2, col3 = st.columns([4, 1.5, 1.5])
IndentationError: unexpected indent

ERROR:root:Module modules.inventory에서 오류 발생: Traceback (most recent call last):
  File "/Users/choenamho/Documents/GitHub/mini-project-2/Home.py", line 48, in <module>
    module = __import__(mod_path, fromlist=[ui_func_name])
  File "/Users/choenamho/Documents/GitHub/mini-project-2/modules/inventory.py", line 114
    col1, col2, col3 = st.columns([4, 1.5, 1.5])
IndentationError: unexpected indent

ERROR:root:Module modules.inventory에서 오류 발생: Traceback (most recent call last):
  File "/Users/choenamho/Documents/GitHub/mini-project-2/Home.py", line 48, in <module>
    module = __import__(mod_path, fromlist=[ui_func_name])
  File "/Users/choenamho/Documents/GitHub/mini-project-2/modules/inventory.py", line 114
    col1, col2, col3 = st.columns([4, 1.5, 1.5])
IndentationError: unexpected indent

ERROR:root:Module modules.inventory에서 오류 발생: Traceback (most recent call last):
  File "/Users/choenamho/Documents/GitHub/mini-project-2/Home.py", line 48, in <module>
    module = __import__(mod_path, fromlist=[ui_func_name])
  File "/Users/choenamho/Documents/GitHub/mini-project-2/modules/inventory.py", line 114
    col1, col2, col3 = st.columns([4, 1.5, 1.5])
IndentationError: unexpected indent

ERROR:root:Module modules.inventory에서 오류 발생: Traceback (most recent call last):
  File "/Users/choenamho/Documents/GitHub/mini-project-2/Home.py", line 48, in <module>
    module = __import__(mod_path, fromlist=[ui_func_name])
  File "/Users/choenamho/Documents/GitHub/mini-project-2/modules/inventory.py", line 114
    col1, col2, col3 = st.columns([4, 1.5, 1.5])
IndentationError: unexpected indent

ERROR:root:Module modules.inventory에서 오류 발생: Traceback (most recent call last):
  File "/Users/choenamho/Documents/GitHub/mini-project-2/Home.py", line 48, in <module>
    module = __import__(mod_path, fromlist=[ui_func_name])
  File "/Users/choenamho/Documents/GitHub/mini-project-2/modules/inventory.py", line 114
    col1, col2, col3 = st.columns([4, 1.5, 1.5])
IndentationError: unexpected indent

ERROR:root:Module modules.inventory에서 오류 발생: Traceback (most recent call last):
  File "/Users/choenamho/Documents/GitHub/mini-project-2/Home.py", line 48, in <module>
    module = __import__(mod_path, fromlist=[ui_func_name])
  File "/Users/choenamho/Documents/GitHub/mini-project-2/modules/inventory.py", line 114
    col1, col2, col3 = st.columns([4, 1.5, 1.5])
IndentationError: unexpected indent

ERROR:root:Module modules.inventory에서 오류 발생: Traceback (most recent call last):
  File "/Users/choenamho/Documents/GitHub/mini-project-2/Home.py", line 48, in <module>
    module = __import__(mod_path, fromlist=[ui_func_name])
  File "/Users/choenamho/Documents/GitHub/mini-project-2/modules/inventory.py", line 114
    col1, col2, col3 = st.columns([4, 1.5, 1.5])
IndentationError: unexpected indent

ERROR:root:Module modules.inventory에서 오류 발생: Traceback (most recent call last):
  File "/Users/choenamho/Documents/GitHub/mini-project-2/Home.py", line 48, in <module>
    module = __import__(mod_path, fromlist=[ui_func_name])
  File "/Users/choenamho/Documents/GitHub/mini-project-2/modules/inventory.py", line 114
    col1, col2, col3 = st.columns([4, 1.5, 1.5])
IndentationError: unexpected indent

ERROR:root:Module modules.inventory에서 오류 발생: Traceback (most recent call last):
  File "/Users/choenamho/Documents/GitHub/mini-project-2/Home.py", line 48, in <module>
    module = __import__(mod_path, fromlist=[ui_func_name])
  File "/Users/choenamho/Documents/GitHub/mini-project-2/modules/inventory.py", line 114
    col1, col2, col3 = st.columns([4, 1.5, 1.5])
IndentationError: unexpected indent

ERROR:root:Module modules.inventory에서 오류 발생: Traceback (most recent call last):
  File "/Users/choenamho/Documents/GitHub/mini-project-2/Home.py", line 48, in <module>
    module = __import__(mod_path, fromlist=[ui_func_name])
  File "/Users/choenamho/Documents/GitHub/mini-project-2/modules/inventory.py", line 114
    col1, col2, col3 = st.columns([4, 1.5, 1.5])
IndentationError: unexpected indent

ERROR:root:Module modules.inventory에서 오류 발생: Traceback (most recent call last):
  File "/Users/choenamho/Documents/GitHub/mini-project-2/Home.py", line 48, in <module>
    module = __import__(mod_path, fromlist=[ui_func_name])
  File "/Users/choenamho/Documents/GitHub/mini-project-2/modules/inventory.py", line 114
    col1, col2, col3 = st.columns([4, 1.5, 1.5])
IndentationError: unexpected indent

ERROR:root:Module modules.inventory에서 오류 발생: Traceback (most recent call last):
  File "/Users/choenamho/Documents/GitHub/mini-project-2/Home.py", line 48, in <module>
    module = __import__(mod_path, fromlist=[ui_func_name])
  File "/Users/choenamho/Documents/GitHub/mini-project-2/modules/inventory.py", line 114
    col1, col2, col3 = st.columns([4, 1.5, 1.5])
IndentationError: unexpected indent

ERROR:root:Module modules.inventory에서 오류 발생: Traceback (most recent call last):
  File "/Users/choenamho/Documents/GitHub/mini-project-2/Home.py", line 48, in <module>
    module = __import__(mod_path, fromlist=[ui_func_name])
  File "/Users/choenamho/Documents/GitHub/mini-project-2/modules/inventory.py", line 114
    col1, col2, col3 = st.columns([4, 1.5, 1.5])
IndentationError: unexpected indent

ERROR:root:Module modules.inventory에서 오류 발생: Traceback (most recent call last):
  File "/Users/choenamho/Documents/GitHub/mini-project-2/Home.py", line 48, in <module>
    module = __import__(mod_path, fromlist=[ui_func_name])
  File "/Users/choenamho/Documents/GitHub/mini-project-2/modules/inventory.py", line 114
    col1, col2, col3 = st.columns([4, 1.5, 1.5])
IndentationError: unexpected indent

ERROR:root:Module modules.inventory에서 오류 발생: Traceback (most recent call last):
  File "/Users/choenamho/Documents/GitHub/mini-project-2/Home.py", line 48, in <module>
    module = __import__(mod_path, fromlist=[ui_func_name])
  File "/Users/choenamho/Documents/GitHub/mini-project-2/modules/inventory.py", line 114
    col1, col2, col3 = st.columns([4, 1.5, 1.5])
IndentationError: unexpected indent

ERROR:root:Module modules.inventory에서 오류 발생: Traceback (most recent call last):
  File "/Users/choenamho/Documents/GitHub/mini-project-2/Home.py", line 48, in <module>
    module = __import__(mod_path, fromlist=[ui_func_name])
  File "/Users/choenamho/Documents/GitHub/mini-project-2/modules/inventory.py", line 133
    st.markdown("""
    ^^
IndentationError: expected an indented block after 'with' statement on line 132

ERROR:root:Module modules.inventory에서 오류 발생: Traceback (most recent call last):
  File "/Users/choenamho/Documents/GitHub/mini-project-2/Home.py", line 48, in <module>
    module = __import__(mod_path, fromlist=[ui_func_name])
  File "/Users/choenamho/Documents/GitHub/mini-project-2/modules/inventory.py", line 133
    st.markdown("""
    ^^
IndentationError: expected an indented block after 'with' statement on line 132

ERROR:root:Module modules.inventory에서 오류 발생: Traceback (most recent call last):
  File "/Users/choenamho/Documents/GitHub/mini-project-2/Home.py", line 48, in <module>
    module = __import__(mod_path, fromlist=[ui_func_name])
  File "/Users/choenamho/Documents/GitHub/mini-project-2/modules/inventory.py", line 114
    col1, col2, col3 = st.columns([4, 1.5, 1.5])
IndentationError: unexpected indent

ERROR:root:Module modules.inventory에서 오류 발생: Traceback (most recent call last):
  File "/Users/choenamho/Documents/GitHub/mini-project-2/Home.py", line 48, in <module>
    module = __import__(mod_path, fromlist=[ui_func_name])
  File "/Users/choenamho/Documents/GitHub/mini-project-2/modules/inventory.py", line 114
    col1, col2, col3 = st.columns([4, 1.5, 1.5])
IndentationError: unexpected indent

ERROR:root:Module modules.inventory에서 오류 발생: Traceback (most recent call last):
  File "/Users/choenamho/Documents/GitHub/mini-project-2/Home.py", line 48, in <module>
    module = __import__(mod_path, fromlist=[ui_func_name])
  File "/Users/choenamho/Documents/GitHub/mini-project-2/modules/inventory.py", line 114
    col1, col2, col3 = st.columns([4, 1.5, 1.5])
IndentationError: unexpected indent

ERROR:root:Module modules.inventory에서 오류 발생: Traceback (most recent call last):
  File "/Users/choenamho/Documents/GitHub/mini-project-2/Home.py", line 48, in <module>
    module = __import__(mod_path, fromlist=[ui_func_name])
  File "/Users/choenamho/Documents/GitHub/mini-project-2/modules/inventory.py", line 114
    col1, col2, col3 = st.columns([4, 1.5, 1.5])
IndentationError: unexpected indent

ERROR:root:Module modules.inventory에서 오류 발생: Traceback (most recent call last):
  File "/Users/choenamho/Documents/GitHub/mini-project-2/Home.py", line 48, in <module>
    module = __import__(mod_path, fromlist=[ui_func_name])
  File "/Users/choenamho/Documents/GitHub/mini-project-2/modules/inventory.py", line 134
    st.markdown("""
    ^^
IndentationError: expected an indented block after 'with' statement on line 133

ERROR:root:Module modules.inventory에서 오류 발생: Traceback (most recent call last):
  File "/Users/choenamho/Documents/GitHub/mini-project-2/Home.py", line 48, in <module>
    module = __import__(mod_path, fromlist=[ui_func_name])
  File "/Users/choenamho/Documents/GitHub/mini-project-2/modules/inventory.py", line 134
    st.markdown("""
    ^^
IndentationError: expected an indented block after 'with' statement on line 133

ERROR:root:Module modules.inventory에서 오류 발생: Traceback (most recent call last):
  File "/Users/choenamho/Documents/GitHub/mini-project-2/Home.py", line 48, in <module>
    module = __import__(mod_path, fromlist=[ui_func_name])
  File "/Users/choenamho/Documents/GitHub/mini-project-2/modules/inventory.py", line 134
    st.markdown("""
    ^^
IndentationError: expected an indented block after 'with' statement on line 133

ERROR:root:Module modules.inventory에서 오류 발생: Traceback (most recent call last):
  File "/Users/choenamho/Documents/GitHub/mini-project-2/Home.py", line 48, in <module>
    module = __import__(mod_path, fromlist=[ui_func_name])
  File "/Users/choenamho/Documents/GitHub/mini-project-2/modules/inventory.py", line 134
    st.markdown("""
    ^^
IndentationError: expected an indented block after 'with' statement on line 133

ERROR:root:Module modules.inventory에서 오류 발생: Traceback (most recent call last):
  File "/Users/choenamho/Documents/GitHub/mini-project-2/Home.py", line 48, in <module>
    module = __import__(mod_path, fromlist=[ui_func_name])
  File "/Users/choenamho/Documents/GitHub/mini-project-2/modules/inventory.py", line 134
    st.markdown("""
    ^^
IndentationError: expected an indented block after 'with' statement on line 133

ERROR:root:Module modules.inventory에서 오류 발생: Traceback (most recent call last):
  File "/Users/choenamho/Documents/GitHub/mini-project-2/Home.py", line 48, in <module>
    module = __import__(mod_path, fromlist=[ui_func_name])
  File "/Users/choenamho/Documents/GitHub/mini-project-2/modules/inventory.py", line 134
    st.markdown("""
    ^^
IndentationError: expected an indented block after 'with' statement on line 133

ERROR:root:Module modules.inventory에서 오류 발생: Traceback (most recent call last):
  File "/Users/choenamho/Documents/GitHub/mini-project-2/Home.py", line 48, in <module>
    module = __import__(mod_path, fromlist=[ui_func_name])
  File "/Users/choenamho/Documents/GitHub/mini-project-2/modules/inventory.py", line 134
    st.markdown("""
    ^^
IndentationError: expected an indented block after 'with' statement on line 133

ERROR:root:Module modules.inventory에서 오류 발생: Traceback (most recent call last):
  File "/Users/choenamho/Documents/GitHub/mini-project-2/Home.py", line 48, in <module>
    module = __import__(mod_path, fromlist=[ui_func_name])
  File "/Users/choenamho/Documents/GitHub/mini-project-2/modules/inventory.py", line 134
    st.markdown("""
    ^^
IndentationError: expected an indented block after 'with' statement on line 133

ERROR:root:Module modules.inventory에서 오류 발생: Traceback (most recent call last):
  File "/Users/choenamho/Documents/GitHub/mini-project-2/Home.py", line 48, in <module>
    module = __import__(mod_path, fromlist=[ui_func_name])
  File "/Users/choenamho/Documents/GitHub/mini-project-2/modules/inventory.py", line 134
    st.markdown("""
    ^^
IndentationError: expected an indented block after 'with' statement on line 133

ERROR:root:Module modules.inventory에서 오류 발생: Traceback (most recent call last):
  File "/Users/choenamho/Documents/GitHub/mini-project-2/Home.py", line 48, in <module>
    module = __import__(mod_path, fromlist=[ui_func_name])
  File "/Users/choenamho/Documents/GitHub/mini-project-2/modules/inventory.py", line 134
    st.markdown("""
    ^^
IndentationError: expected an indented block after 'with' statement on line 133

ERROR:root:Module modules.inventory에서 오류 발생: Traceback (most recent call last):
  File "/Users/choenamho/Documents/GitHub/mini-project-2/Home.py", line 48, in <module>
    module = __import__(mod_path, fromlist=[ui_func_name])
  File "/Users/choenamho/Documents/GitHub/mini-project-2/modules/inventory.py", line 130, in <module>
    filtered = inventory_df[inventory_df["연도"] == year_sel]
NameError: name 'inventory_df' is not defined. Did you mean: 'inventory_ui'?

ERROR:root:Module modules.inventory에서 오류 발생: Traceback (most recent call last):
  File "/Users/choenamho/Documents/GitHub/mini-project-2/Home.py", line 48, in <module>
    module = __import__(mod_path, fromlist=[ui_func_name])
  File "/Users/choenamho/Documents/GitHub/mini-project-2/modules/inventory.py", line 130, in <module>
    filtered = inventory_df[inventory_df["연도"] == year_sel]
NameError: name 'inventory_df' is not defined. Did you mean: 'inventory_ui'?

